Workbook

Sheet Gemini抽出データ

Sheet シール
A1: 1 | B1: =OFFSET(Gemini抽出データ!$A$1,A1,0) -> 0 | D1: =A1+1 -> 2 | E1: =OFFSET(Gemini抽出データ!$A$1,D1,0) -> 0 | G1: =D1+1 -> 3 | H1: =OFFSET(Gemini抽出データ!$A$1,G1,0) -> 0 | J1: =G1+1 -> 4 | K1: =OFFSET(Gemini抽出データ!$A$1,J1,0) -> 0 | M1: =J43+1 -> 29 | N1: =OFFSET(Gemini抽出データ!$A$1,M1,0) -> 0 | P1: =M1+1 -> 30 | Q1: =OFFSET(Gemini抽出データ!$A$1,P1,0) -> 0 | S1: =P1+1 -> 31 | T1: =OFFSET(Gemini抽出データ!$A$1,S1,0) -> 0 | V1: =S1+1 -> 32 | W1: =OFFSET(Gemini抽出データ!$A$1,V1,0) -> 0 | Y1: =V43+1 -> 57 | Z1: =OFFSET(Gemini抽出データ!$A$1,Y1,0) -> 0 | AB1: =Y1+1 -> 58 | AC1: =OFFSET(Gemini抽出データ!$A$1,AB1,0) -> 0 | AE1: =AB1+1 -> 59 | AF1: =OFFSET(Gemini抽出データ!$A$1,AE1,0) -> 0 | AH1: =AE1+1 -> 60 | AI1: =OFFSET(Gemini抽出データ!$A$1,AH1,0) -> 0 | AK1: =AH43+1 -> 85 | AL1: =OFFSET(Gemini抽出データ!$A$1,AK1,0) -> 0 | AN1: =AK1+1 -> 86 | AO1: =OFFSET(Gemini抽出データ!$A$1,AN1,0) -> 0 | AQ1: =AN1+1 -> 87 | AR1: =OFFSET(Gemini抽出データ!$A$1,AQ1,0) -> 0 | AT1: =AQ1+1 -> 88 | AU1: =OFFSET(Gemini抽出データ!$A$1,AT1,0) -> 0 | AW1: =AT43+1 -> 113 | AX1: =OFFSET(Gemini抽出データ!$A$1,AW1,0) -> 0 | AZ1: =AW1+1 -> 114 | BA1: =OFFSET(Gemini抽出データ!$A$1,AZ1,0) -> 0 | BC1: =AZ1+1 -> 115 | BD1: =OFFSET(Gemini抽出データ!$A$1,BC1,0) -> 0 | BF1: =BC1+1 -> 116 | BG1: =OFFSET(Gemini抽出データ!$A$1,BF1,0) -> 0 | BI1: =BF43+1 -> 141 | BJ1: =OFFSET(Gemini抽出データ!$A$1,BI1,0) -> 0 | BL1: =BI1+1 -> 142 | BM1: =OFFSET(Gemini抽出データ!$A$1,BL1,0) -> 0 | BO1: =BL1+1 -> 143 | BP1: =OFFSET(Gemini抽出データ!$A$1,BO1,0) -> 0 | BR1: =BO1+1 -> 144 | BS1: =OFFSET(Gemini抽出データ!$A$1,BR1,0) -> 0 | BU1: =BR43+1 -> 169 | BV1: =OFFSET(Gemini抽出データ!$A$1,BU1,0) -> 0 | BX1: =BU1+1 -> 170 | BY1: =OFFSET(Gemini抽出データ!$A$1,BX1,0) -> 0 | CA1: =BX1+1 -> 171 | CB1: =OFFSET(Gemini抽出データ!$A$1,CA1,0) -> 0 | CD1: =CA1+1 -> 172 | CE1: =OFFSET(Gemini抽出データ!$A$1,CD1,0) -> 0 | CG1: =CD43+1 -> 197 | CH1: =OFFSET(Gemini抽出データ!$A$1,CG1,0) -> 0 | CJ1: =CG1+1 -> 198 | CK1: =OFFSET(Gemini抽出データ!$A$1,CJ1,0) -> 0 | CM1: =CJ1+1 -> 199 | CN1: =OFFSET(Gemini抽出データ!$A$1,CM1,0) -> 0 | CP1: =CM1+1 -> 200 | CQ1: =OFFSET(Gemini抽出データ!$A$1,CP1,0) -> 0 | CS1: =CP43+1 -> 225 | CT1: =OFFSET(Gemini抽出データ!$A$1,CS1,0) -> 0 | CV1: =CS1+1 -> 226 | CW1: =OFFSET(Gemini抽出データ!$A$1,CV1,0) -> 0 | CY1: =CV1+1 -> 227 | CZ1: =OFFSET(Gemini抽出データ!$A$1,CY1,0) -> 0 | DB1: =CY1+1 -> 228 | DC1: =OFFSET(Gemini抽出データ!$A$1,DB1,0) -> 0 | DE1: =DB43+1 -> 253 | DF1: =OFFSET(Gemini抽出データ!$A$1,DE1,0) -> 0 | DH1: =DE1+1 -> 254 | DI1: =OFFSET(Gemini抽出データ!$A$1,DH1,0) -> 0 | DK1: =DH1+1 -> 255 | DL1: =OFFSET(Gemini抽出データ!$A$1,DK1,0) -> 0 | DN1: =DK1+1 -> 256 | DO1: =OFFSET(Gemini抽出データ!$A$1,DN1,0) -> 0 | DQ1: =DN43+1 -> 281 | DR1: =OFFSET(Gemini抽出データ!$A$1,DQ1,0) -> 0 | DT1: =DQ1+1 -> 282 | DU1: =OFFSET(Gemini抽出データ!$A$1,DT1,0) -> 0 | DW1: =DT1+1 -> 283 | DX1: =OFFSET(Gemini抽出データ!$A$1,DW1,0) -> 0 | DZ1: =DW1+1 -> 284 | EA1: =OFFSET(Gemini抽出データ!$A$1,DZ1,0) -> 0 | EC1: =DZ43+1 -> 309 | ED1: =OFFSET(Gemini抽出データ!$A$1,EC1,0) -> 0 | EF1: =EC1+1 -> 310 | EG1: =OFFSET(Gemini抽出データ!$A$1,EF1,0) -> 0 | EI1: =EF1+1 -> 311 | EJ1: =OFFSET(Gemini抽出データ!$A$1,EI1,0) -> 0 | EL1: =EI1+1 -> 312 | EM1: =OFFSET(Gemini抽出データ!$A$1,EL1,0) -> 0 | EO1: =EL43+1 -> 337 | EP1: =OFFSET(Gemini抽出データ!$A$1,EO1,0) -> 0 | ER1: =EO1+1 -> 338 | ES1: =OFFSET(Gemini抽出データ!$A$1,ER1,0) -> 0 | EU1: =ER1+1 -> 339 | EV1: =OFFSET(Gemini抽出データ!$A$1,EU1,0) -> 0 | EX1: =EU1+1 -> 340 | EY1: =OFFSET(Gemini抽出データ!$A$1,EX1,0) -> 0 | FA1: =EX43+1 -> 365 | FB1: =OFFSET(Gemini抽出データ!$A$1,FA1,0) -> 0 | FD1: =FA1+1 -> 366 | FE1: =OFFSET(Gemini抽出データ!$A$1,FD1,0) -> 0 | FG1: =FD1+1 -> 367 | FH1: =OFFSET(Gemini抽出データ!$A$1,FG1,0) -> 0 | FJ1: =FG1+1 -> 368 | FK1: =OFFSET(Gemini抽出データ!$A$1,FJ1,0) -> 0 | FM1: =FJ43+1 -> 393 | FN1: =OFFSET(Gemini抽出データ!$A$1,FM1,0) -> 0 | FP1: =FM1+1 -> 394 | FQ1: =OFFSET(Gemini抽出データ!$A$1,FP1,0) -> 0 | FS1: =FP1+1 -> 395 | FT1: =OFFSET(Gemini抽出データ!$A$1,FS1,0) -> 0 | FV1: =FS1+1 -> 396 | FW1: =OFFSET(Gemini抽出データ!$A$1,FV1,0) -> 0 | FY1: =FV43+1 -> 421 | FZ1: =OFFSET(Gemini抽出データ!$A$1,FY1,0) -> 0 | GB1: =FY1+1 -> 422 | GC1: =OFFSET(Gemini抽出データ!$A$1,GB1,0) -> 0 | GE1: =GB1+1 -> 423 | GF1: =OFFSET(Gemini抽出データ!$A$1,GE1,0) -> 0 | GH1: =GE1+1 -> 424 | GI1: =OFFSET(Gemini抽出データ!$A$1,GH1,0) -> 0 | GK1: =GH43+1 -> 449 | GL1: =OFFSET(Gemini抽出データ!$A$1,GK1,0) -> 0 | GN1: =GK1+1 -> 450 | GO1: =OFFSET(Gemini抽出データ!$A$1,GN1,0) -> 0 | GQ1: =GN1+1 -> 451 | GR1: =OFFSET(Gemini抽出データ!$A$1,GQ1,0) -> 0 | GT1: =GQ1+1 -> 452 | GU1: =OFFSET(Gemini抽出データ!$A$1,GT1,0) -> 0 | GW1: =GT43+1 -> 477 | GX1: =OFFSET(Gemini抽出データ!$A$1,GW1,0) -> 0 | GZ1: =GW1+1 -> 478 | HA1: =OFFSET(Gemini抽出データ!$A$1,GZ1,0) -> 0 | HC1: =GZ1+1 -> 479 | HD1: =OFFSET(Gemini抽出データ!$A$1,HC1,0) -> 0 | HF1: =HC1+1 -> 480 | HG1: =OFFSET(Gemini抽出データ!$A$1,HF1,0) -> 0 | HI1: =HF43+1 -> 505 | HJ1: =OFFSET(Gemini抽出データ!$A$1,HI1,0) -> 0 | HL1: =HI1+1 -> 506 | HM1: =OFFSET(Gemini抽出データ!$A$1,HL1,0) -> 0 | HO1: =HL1+1 -> 507 | HP1: =OFFSET(Gemini抽出データ!$A$1,HO1,0) -> 0 | HR1: =HO1+1 -> 508 | HS1: =OFFSET(Gemini抽出データ!$A$1,HR1,0) -> 0 | HU1: =OFFSET(Gemini抽出データ!$A$1,#REF!,0) -> #REF!
A2: ="クライアント名"&A$1 -> クライアント名1 | B2: =OFFSET(Gemini抽出データ!$A$1,A1,2) -> 0 | D2: ="クライアント名"&D$1 -> クライアント名2 | E2: =OFFSET(Gemini抽出データ!$A$1,D1,2) -> 0 | G2: ="クライアント名"&G$1 -> クライアント名3 | H2: =OFFSET(Gemini抽出データ!$A$1,G1,2) -> 0 | J2: ="クライアント名"&J$1 -> クライアント名4 | K2: =OFFSET(Gemini抽出データ!$A$1,J1,2) -> 0 | M2: ="クライアント名"&M$1 -> クライアント名29 | N2: =OFFSET(Gemini抽出データ!$A$1,M1,2) -> 0 | P2: ="クライアント名"&P$1 -> クライアント名30 | Q2: =OFFSET(Gemini抽出データ!$A$1,P1,2) -> 0 | S2: ="クライアント名"&S$1 -> クライアント名31 | T2: =OFFSET(Gemini抽出データ!$A$1,S1,2) -> 0 | V2: ="クライアント名"&V$1 -> クライアント名32 | W2: =OFFSET(Gemini抽出データ!$A$1,V1,2) -> 0 | Y2: ="クライアント名"&Y$1 -> クライアント名57 | Z2: =OFFSET(Gemini抽出データ!$A$1,Y1,2) -> 0 | AB2: ="クライアント名"&AB$1 -> クライアント名58 | AC2: =OFFSET(Gemini抽出データ!$A$1,AB1,2) -> 0 | AE2: ="クライアント名"&AE$1 -> クライアント名59 | AF2: =OFFSET(Gemini抽出データ!$A$1,AE1,2) -> 0 | AH2: ="クライアント名"&AH$1 -> クライアント名60 | AI2: =OFFSET(Gemini抽出データ!$A$1,AH1,2) -> 0 | AK2: ="クライアント名"&AK$1 -> クライアント名85 | AL2: =OFFSET(Gemini抽出データ!$A$1,AK1,2) -> 0 | AN2: ="クライアント名"&AN$1 -> クライアント名86 | AO2: =OFFSET(Gemini抽出データ!$A$1,AN1,2) -> 0 | AQ2: ="クライアント名"&AQ$1 -> クライアント名87 | AR2: =OFFSET(Gemini抽出データ!$A$1,AQ1,2) -> 0 | AT2: ="クライアント名"&AT$1 -> クライアント名88 | AU2: =OFFSET(Gemini抽出データ!$A$1,AT1,2) -> 0 | AW2: ="クライアント名"&AW$1 -> クライアント名113 | AX2: =OFFSET(Gemini抽出データ!$A$1,AW1,2) -> 0 | AZ2: ="クライアント名"&AZ$1 -> クライアント名114 | BA2: =OFFSET(Gemini抽出データ!$A$1,AZ1,2) -> 0 | BC2: ="クライアント名"&BC$1 -> クライアント名115 | BD2: =OFFSET(Gemini抽出データ!$A$1,BC1,2) -> 0 | BF2: ="クライアント名"&BF$1 -> クライアント名116 | BG2: =OFFSET(Gemini抽出データ!$A$1,BF1,2) -> 0 | BI2: ="クライアント名"&BI$1 -> クライアント名141 | BJ2: =OFFSET(Gemini抽出データ!$A$1,BI1,2) -> 0 | BL2: ="クライアント名"&BL$1 -> クライアント名142 | BM2: =OFFSET(Gemini抽出データ!$A$1,BL1,2) -> 0 | BO2: ="クライアント名"&BO$1 -> クライアント名143 | BP2: =OFFSET(Gemini抽出データ!$A$1,BO1,2) -> 0 | BR2: ="クライアント名"&BR$1 -> クライアント名144 | BS2: =OFFSET(Gemini抽出データ!$A$1,BR1,2) -> 0 | BU2: ="クライアント名"&BU$1 -> クライアント名169 | BV2: =OFFSET(Gemini抽出データ!$A$1,BU1,2) -> 0 | BX2: ="クライアント名"&BX$1 -> クライアント名170 | BY2: =OFFSET(Gemini抽出データ!$A$1,BX1,2) -> 0 | CA2: ="クライアント名"&CA$1 -> クライアント名171 | CB2: =OFFSET(Gemini抽出データ!$A$1,CA1,2) -> 0 | CD2: ="クライアント名"&CD$1 -> クライアント名172 | CE2: =OFFSET(Gemini抽出データ!$A$1,CD1,2) -> 0 | CG2: ="クライアント名"&CG$1 -> クライアント名197 | CH2: =OFFSET(Gemini抽出データ!$A$1,CG1,2) -> 0 | CJ2: ="クライアント名"&CJ$1 -> クライアント名198 | CK2: =OFFSET(Gemini抽出データ!$A$1,CJ1,2) -> 0 | CM2: ="クライアント名"&CM$1 -> クライアント名199 | CN2: =OFFSET(Gemini抽出データ!$A$1,CM1,2) -> 0 | CP2: ="クライアント名"&CP$1 -> クライアント名200 | CQ2: =OFFSET(Gemini抽出データ!$A$1,CP1,2) -> 0 | CS2: ="クライアント名"&CS$1 -> クライアント名225 | CT2: =OFFSET(Gemini抽出データ!$A$1,CS1,2) -> 0 | CV2: ="クライアント名"&CV$1 -> クライアント名226 | CW2: =OFFSET(Gemini抽出データ!$A$1,CV1,2) -> 0 | CY2: ="クライアント名"&CY$1 -> クライアント名227 | CZ2: =OFFSET(Gemini抽出データ!$A$1,CY1,2) -> 0 | DB2: ="クライアント名"&DB$1 -> クライアント名228 | DC2: =OFFSET(Gemini抽出データ!$A$1,DB1,2) -> 0 | DE2: ="クライアント名"&DE$1 -> クライアント名253 | DF2: =OFFSET(Gemini抽出データ!$A$1,DE1,2) -> 0 | DH2: ="クライアント名"&DH$1 -> クライアント名254 | DI2: =OFFSET(Gemini抽出データ!$A$1,DH1,2) -> 0 | DK2: ="クライアント名"&DK$1 -> クライアント名255 | DL2: =OFFSET(Gemini抽出データ!$A$1,DK1,2) -> 0 | DN2: ="クライアント名"&DN$1 -> クライアント名256 | DO2: =OFFSET(Gemini抽出データ!$A$1,DN1,2) -> 0 | DQ2: ="クライアント名"&DQ$1 -> クライアント名281 | DR2: =OFFSET(Gemini抽出データ!$A$1,DQ1,2) -> 0 | DT2: ="クライアント名"&DT$1 -> クライアント名282 | DU2: =OFFSET(Gemini抽出データ!$A$1,DT1,2) -> 0 | DW2: ="クライアント名"&DW$1 -> クライアント名283 | DX2: =OFFSET(Gemini抽出データ!$A$1,DW1,2) -> 0 | DZ2: ="クライアント名"&DZ$1 -> クライアント名284 | EA2: =OFFSET(Gemini抽出データ!$A$1,DZ1,2) -> 0 | EC2: ="クライアント名"&EC$1 -> クライアント名309 | ED2: =OFFSET(Gemini抽出データ!$A$1,EC1,2) -> 0 | EF2: ="クライアント名"&EF$1 -> クライアント名310 | EG2: =OFFSET(Gemini抽出データ!$A$1,EF1,2) -> 0 | EI2: ="クライアント名"&EI$1 -> クライアント名311 | EJ2: =OFFSET(Gemini抽出データ!$A$1,EI1,2) -> 0 | EL2: ="クライアント名"&EL$1 -> クライアント名312 | EM2: =OFFSET(Gemini抽出データ!$A$1,EL1,2) -> 0 | EO2: ="クライアント名"&EO$1 -> クライアント名337 | EP2: =OFFSET(Gemini抽出データ!$A$1,EO1,2) -> 0 | ER2: ="クライアント名"&ER$1 -> クライアント名338 | ES2: =OFFSET(Gemini抽出データ!$A$1,ER1,2) -> 0 | EU2: ="クライアント名"&EU$1 -> クライアント名339 | EV2: =OFFSET(Gemini抽出データ!$A$1,EU1,2) -> 0 | EX2: ="クライアント名"&EX$1 -> クライアント名340 | EY2: =OFFSET(Gemini抽出データ!$A$1,EX1,2) -> 0 | FA2: ="クライアント名"&FA$1 -> クライアント名365 | FB2: =OFFSET(Gemini抽出データ!$A$1,FA1,2) -> 0 | FD2: ="クライアント名"&FD$1 -> クライアント名366 | FE2: =OFFSET(Gemini抽出データ!$A$1,FD1,2) -> 0 | FG2: ="クライアント名"&FG$1 -> クライアント名367 | FH2: =OFFSET(Gemini抽出データ!$A$1,FG1,2) -> 0 | FJ2: ="クライアント名"&FJ$1 -> クライアント名368 | FK2: =OFFSET(Gemini抽出データ!$A$1,FJ1,2) -> 0 | FM2: ="クライアント名"&FM$1 -> クライアント名393 | FN2: =OFFSET(Gemini抽出データ!$A$1,FM1,2) -> 0 | FP2: ="クライアント名"&FP$1 -> クライアント名394 | FQ2: =OFFSET(Gemini抽出データ!$A$1,FP1,2) -> 0 | FS2: ="クライアント名"&FS$1 -> クライアント名395 | FT2: =OFFSET(Gemini抽出データ!$A$1,FS1,2) -> 0 | FV2: ="クライアント名"&FV$1 -> クライアント名396 | FW2: =OFFSET(Gemini抽出データ!$A$1,FV1,2) -> 0 | FY2: ="クライアント名"&FY$1 -> クライアント名421 | FZ2: =OFFSET(Gemini抽出データ!$A$1,FY1,2) -> 0 | GB2: ="クライアント名"&GB$1 -> クライアント名422 | GC2: =OFFSET(Gemini抽出データ!$A$1,GB1,2) -> 0 | GE2: ="クライアント名"&GE$1 -> クライアント名423 | GF2: =OFFSET(Gemini抽出データ!$A$1,GE1,2) -> 0 | GH2: ="クライアント名"&GH$1 -> クライアント名424 | GI2: =OFFSET(Gemini抽出データ!$A$1,GH1,2) -> 0 | GK2: ="クライアント名"&GK$1 -> クライアント名449 | GL2: =OFFSET(Gemini抽出データ!$A$1,GK1,2) -> 0 | GN2: ="クライアント名"&GN$1 -> クライアント名450 | GO2: =OFFSET(Gemini抽出データ!$A$1,GN1,2) -> 0 | GQ2: ="クライアント名"&GQ$1 -> クライアント名451 | GR2: =OFFSET(Gemini抽出データ!$A$1,GQ1,2) -> 0 | GT2: ="クライアント名"&GT$1 -> クライアント名452 | GU2: =OFFSET(Gemini抽出データ!$A$1,GT1,2) -> 0 | GW2: ="クライアント名"&GW$1 -> クライアント名477 | GX2: =OFFSET(Gemini抽出データ!$A$1,GW1,2) -> 0 | GZ2: ="クライアント名"&GZ$1 -> クライアント名478 | HA2: =OFFSET(Gemini抽出データ!$A$1,GZ1,2) -> 0 | HC2: ="クライアント名"&HC$1 -> クライアント名479 | HD2: =OFFSET(Gemini抽出データ!$A$1,HC1,2) -> 0 | HF2: ="クライアント名"&HF$1 -> クライアント名480 | HG2: =OFFSET(Gemini抽出データ!$A$1,HF1,2) -> 0 | HI2: ="クライアント名"&HI$1 -> クライアント名505 | HJ2: =OFFSET(Gemini抽出データ!$A$1,HI1,2) -> 0 | HL2: ="クライアント名"&HL$1 -> クライアント名506 | HM2: =OFFSET(Gemini抽出データ!$A$1,HL1,2) -> 0 | HO2: ="クライアント名"&HO$1 -> クライアント名507 | HP2: =OFFSET(Gemini抽出データ!$A$1,HO1,2) -> 0 | HR2: ="クライアント名"&HR$1 -> クライアント名508 | HS2: =OFFSET(Gemini抽出データ!$A$1,HR1,2) -> 0 | HU2: =OFFSET(Gemini抽出データ!$A$1,#REF!,2) -> #REF!
A3: ="種類"&A$1 -> 種類1 | B3: =IF(OFFSET(Gemini抽出データ!$A$1,A1,1)=0,"",OFFSET(Gemini抽出データ!$A$1,A1,1)) | D3: ="学年"&D$1 -> 学年2 | E3: =IF(OFFSET(Gemini抽出データ!$A$1,D1,1)=0,"",OFFSET(Gemini抽出データ!$A$1,D1,1)) | G3: ="学年"&G$1 -> 学年3 | H3: =IF(OFFSET(Gemini抽出データ!$A$1,G1,1)=0,"",OFFSET(Gemini抽出データ!$A$1,G1,1)) | J3: ="学年"&J$1 -> 学年4 | K3: =IF(OFFSET(Gemini抽出データ!$A$1,J1,1)=0,"",OFFSET(Gemini抽出データ!$A$1,J1,1)) | M3: ="種類"&M$1 -> 種類29 | N3: =IF(OFFSET(Gemini抽出データ!$A$1,M1,1)=0,"",OFFSET(Gemini抽出データ!$A$1,M1,1)) | P3: ="学年"&P$1 -> 学年30 | Q3: =IF(OFFSET(Gemini抽出データ!$A$1,P1,1)=0,"",OFFSET(Gemini抽出データ!$A$1,P1,1)) | S3: ="学年"&S$1 -> 学年31 | T3: =IF(OFFSET(Gemini抽出データ!$A$1,S1,1)=0,"",OFFSET(Gemini抽出データ!$A$1,S1,1)) | V3: ="学年"&V$1 -> 学年32 | W3: =IF(OFFSET(Gemini抽出データ!$A$1,V1,1)=0,"",OFFSET(Gemini抽出データ!$A$1,V1,1)) | Y3: ="種類"&Y$1 -> 種類57 | Z3: =IF(OFFSET(Gemini抽出データ!$A$1,Y1,1)=0,"",OFFSET(Gemini抽出データ!$A$1,Y1,1)) | AB3: ="学年"&AB$1 -> 学年58 | AC3: =IF(OFFSET(Gemini抽出データ!$A$1,AB1,1)=0,"",OFFSET(Gemini抽出データ!$A$1,AB1,1)) | AE3: ="学年"&AE$1 -> 学年59 | AF3: =IF(OFFSET(Gemini抽出データ!$A$1,AE1,1)=0,"",OFFSET(Gemini抽出データ!$A$1,AE1,1)) | AH3: ="学年"&AH$1 -> 学年60 | AI3: =IF(OFFSET(Gemini抽出データ!$A$1,AH1,1)=0,"",OFFSET(Gemini抽出データ!$A$1,AH1,1)) | AK3: ="種類"&AK$1 -> 種類85 | AL3: =IF(OFFSET(Gemini抽出データ!$A$1,AK1,1)=0,"",OFFSET(Gemini抽出データ!$A$1,AK1,1)) | AN3: ="学年"&AN$1 -> 学年86 | AO3: =IF(OFFSET(Gemini抽出データ!$A$1,AN1,1)=0,"",OFFSET(Gemini抽出データ!$A$1,AN1,1)) | AQ3: ="学年"&AQ$1 -> 学年87 | AR3: =IF(OFFSET(Gemini抽出データ!$A$1,AQ1,1)=0,"",OFFSET(Gemini抽出データ!$A$1,AQ1,1)) | AT3: ="学年"&AT$1 -> 学年88 | AU3: =IF(OFFSET(Gemini抽出データ!$A$1,AT1,1)=0,"",OFFSET(Gemini抽出データ!$A$1,AT1,1)) | AW3: ="種類"&AW$1 -> 種類113 | AX3: =IF(OFFSET(Gemini抽出データ!$A$1,AW1,1)=0,"",OFFSET(Gemini抽出データ!$A$1,AW1,1)) | AZ3: ="学年"&AZ$1 -> 学年114 | BA3: =IF(OFFSET(Gemini抽出データ!$A$1,AZ1,1)=0,"",OFFSET(Gemini抽出データ!$A$1,AZ1,1)) | BC3: ="学年"&BC$1 -> 学年115 | BD3: =IF(OFFSET(Gemini抽出データ!$A$1,BC1,1)=0,"",OFFSET(Gemini抽出データ!$A$1,BC1,1)) | BF3: ="学年"&BF$1 -> 学年116 | BG3: =IF(OFFSET(Gemini抽出データ!$A$1,BF1,1)=0,"",OFFSET(Gemini抽出データ!$A$1,BF1,1)) | BI3: ="種類"&BI$1 -> 種類141 | BJ3: =IF(OFFSET(Gemini抽出データ!$A$1,BI1,1)=0,"",OFFSET(Gemini抽出データ!$A$1,BI1,1)) | BL3: ="学年"&BL$1 -> 学年142 | BM3: =IF(OFFSET(Gemini抽出データ!$A$1,BL1,1)=0,"",OFFSET(Gemini抽出データ!$A$1,BL1,1)) | BO3: ="学年"&BO$1 -> 学年143 | BP3: =IF(OFFSET(Gemini抽出データ!$A$1,BO1,1)=0,"",OFFSET(Gemini抽出データ!$A$1,BO1,1)) | BR3: ="学年"&BR$1 -> 学年144 | BS3: =IF(OFFSET(Gemini抽出データ!$A$1,BR1,1)=0,"",OFFSET(Gemini抽出データ!$A$1,BR1,1)) | BU3: ="種類"&BU$1 -> 種類169 | BV3: =IF(OFFSET(Gemini抽出データ!$A$1,BU1,1)=0,"",OFFSET(Gemini抽出データ!$A$1,BU1,1)) | BX3: ="学年"&BX$1 -> 学年170 | BY3: =IF(OFFSET(Gemini抽出データ!$A$1,BX1,1)=0,"",OFFSET(Gemini抽出データ!$A$1,BX1,1)) | CA3: ="学年"&CA$1 -> 学年171 | CB3: =IF(OFFSET(Gemini抽出データ!$A$1,CA1,1)=0,"",OFFSET(Gemini抽出データ!$A$1,CA1,1)) | CD3: ="学年"&CD$1 -> 学年172 | CE3: =IF(OFFSET(Gemini抽出データ!$A$1,CD1,1)=0,"",OFFSET(Gemini抽出データ!$A$1,CD1,1)) | CG3: ="種類"&CG$1 -> 種類197 | CH3: =IF(OFFSET(Gemini抽出データ!$A$1,CG1,1)=0,"",OFFSET(Gemini抽出データ!$A$1,CG1,1)) | CJ3: ="学年"&CJ$1 -> 学年198 | CK3: =IF(OFFSET(Gemini抽出データ!$A$1,CJ1,1)=0,"",OFFSET(Gemini抽出データ!$A$1,CJ1,1)) | CM3: ="学年"&CM$1 -> 学年199 | CN3: =IF(OFFSET(Gemini抽出データ!$A$1,CM1,1)=0,"",OFFSET(Gemini抽出データ!$A$1,CM1,1)) | CP3: ="学年"&CP$1 -> 学年200 | CQ3: =IF(OFFSET(Gemini抽出データ!$A$1,CP1,1)=0,"",OFFSET(Gemini抽出データ!$A$1,CP1,1)) | CS3: ="種類"&CS$1 -> 種類225 | CT3: =IF(OFFSET(Gemini抽出データ!$A$1,CS1,1)=0,"",OFFSET(Gemini抽出データ!$A$1,CS1,1)) | CV3: ="学年"&CV$1 -> 学年226 | CW3: =IF(OFFSET(Gemini抽出データ!$A$1,CV1,1)=0,"",OFFSET(Gemini抽出データ!$A$1,CV1,1)) | CY3: ="学年"&CY$1 -> 学年227 | CZ3: =IF(OFFSET(Gemini抽出データ!$A$1,CY1,1)=0,"",OFFSET(Gemini抽出データ!$A$1,CY1,1)) | DB3: ="学年"&DB$1 -> 学年228 | DC3: =IF(OFFSET(Gemini抽出データ!$A$1,DB1,1)=0,"",OFFSET(Gemini抽出データ!$A$1,DB1,1)) | DE3: ="種類"&DE$1 -> 種類253 | DF3: =IF(OFFSET(Gemini抽出データ!$A$1,DE1,1)=0,"",OFFSET(Gemini抽出データ!$A$1,DE1,1)) | DH3: ="学年"&DH$1 -> 学年254 | DI3: =IF(OFFSET(Gemini抽出データ!$A$1,DH1,1)=0,"",OFFSET(Gemini抽出データ!$A$1,DH1,1)) | DK3: ="学年"&DK$1 -> 学年255 | DL3: =IF(OFFSET(Gemini抽出データ!$A$1,DK1,1)=0,"",OFFSET(Gemini抽出データ!$A$1,DK1,1)) | DN3: ="学年"&DN$1 -> 学年256 | DO3: =IF(OFFSET(Gemini抽出データ!$A$1,DN1,1)=0,"",OFFSET(Gemini抽出データ!$A$1,DN1,1)) | DQ3: ="種類"&DQ$1 -> 種類281 | DR3: =IF(OFFSET(Gemini抽出データ!$A$1,DQ1,1)=0,"",OFFSET(Gemini抽出データ!$A$1,DQ1,1)) | DT3: ="学年"&DT$1 -> 学年282 | DU3: =IF(OFFSET(Gemini抽出データ!$A$1,DT1,1)=0,"",OFFSET(Gemini抽出データ!$A$1,DT1,1)) | DW3: ="学年"&DW$1 -> 学年283 | DX3: =IF(OFFSET(Gemini抽出データ!$A$1,DW1,1)=0,"",OFFSET(Gemini抽出データ!$A$1,DW1,1)) | DZ3: ="学年"&DZ$1 -> 学年284 | EA3: =IF(OFFSET(Gemini抽出データ!$A$1,DZ1,1)=0,"",OFFSET(Gemini抽出データ!$A$1,DZ1,1)) | EC3: ="種類"&EC$1 -> 種類309 | ED3: =IF(OFFSET(Gemini抽出データ!$A$1,EC1,1)=0,"",OFFSET(Gemini抽出データ!$A$1,EC1,1)) | EF3: ="学年"&EF$1 -> 学年310 | EG3: =IF(OFFSET(Gemini抽出データ!$A$1,EF1,1)=0,"",OFFSET(Gemini抽出データ!$A$1,EF1,1)) | EI3: ="学年"&EI$1 -> 学年311 | EJ3: =IF(OFFSET(Gemini抽出データ!$A$1,EI1,1)=0,"",OFFSET(Gemini抽出データ!$A$1,EI1,1)) | EL3: ="学年"&EL$1 -> 学年312 | EM3: =IF(OFFSET(Gemini抽出データ!$A$1,EL1,1)=0,"",OFFSET(Gemini抽出データ!$A$1,EL1,1)) | EO3: ="種類"&EO$1 -> 種類337 | EP3: =IF(OFFSET(Gemini抽出データ!$A$1,EO1,1)=0,"",OFFSET(Gemini抽出データ!$A$1,EO1,1)) | ER3: ="学年"&ER$1 -> 学年338 | ES3: =IF(OFFSET(Gemini抽出データ!$A$1,ER1,1)=0,"",OFFSET(Gemini抽出データ!$A$1,ER1,1)) | EU3: ="学年"&EU$1 -> 学年339 | EV3: =IF(OFFSET(Gemini抽出データ!$A$1,EU1,1)=0,"",OFFSET(Gemini抽出データ!$A$1,EU1,1)) | EX3: ="学年"&EX$1 -> 学年340 | EY3: =IF(OFFSET(Gemini抽出データ!$A$1,EX1,1)=0,"",OFFSET(Gemini抽出データ!$A$1,EX1,1)) | FA3: ="種類"&FA$1 -> 種類365 | FB3: =IF(OFFSET(Gemini抽出データ!$A$1,FA1,1)=0,"",OFFSET(Gemini抽出データ!$A$1,FA1,1)) | FD3: ="学年"&FD$1 -> 学年366 | FE3: =IF(OFFSET(Gemini抽出データ!$A$1,FD1,1)=0,"",OFFSET(Gemini抽出データ!$A$1,FD1,1)) | FG3: ="学年"&FG$1 -> 学年367 | FH3: =IF(OFFSET(Gemini抽出データ!$A$1,FG1,1)=0,"",OFFSET(Gemini抽出データ!$A$1,FG1,1)) | FJ3: ="学年"&FJ$1 -> 学年368 | FK3: =IF(OFFSET(Gemini抽出データ!$A$1,FJ1,1)=0,"",OFFSET(Gemini抽出データ!$A$1,FJ1,1)) | FM3: ="種類"&FM$1 -> 種類393 | FN3: =IF(OFFSET(Gemini抽出データ!$A$1,FM1,1)=0,"",OFFSET(Gemini抽出データ!$A$1,FM1,1)) | FP3: ="学年"&FP$1 -> 学年394 | FQ3: =IF(OFFSET(Gemini抽出データ!$A$1,FP1,1)=0,"",OFFSET(Gemini抽出データ!$A$1,FP1,1)) | FS3: ="学年"&FS$1 -> 学年395 | FT3: =IF(OFFSET(Gemini抽出データ!$A$1,FS1,1)=0,"",OFFSET(Gemini抽出データ!$A$1,FS1,1)) | FV3: ="学年"&FV$1 -> 学年396 | FW3: =IF(OFFSET(Gemini抽出データ!$A$1,FV1,1)=0,"",OFFSET(Gemini抽出データ!$A$1,FV1,1)) | FY3: ="種類"&FY$1 -> 種類421 | FZ3: =IF(OFFSET(Gemini抽出データ!$A$1,FY1,1)=0,"",OFFSET(Gemini抽出データ!$A$1,FY1,1)) | GB3: ="学年"&GB$1 -> 学年422 | GC3: =IF(OFFSET(Gemini抽出データ!$A$1,GB1,1)=0,"",OFFSET(Gemini抽出データ!$A$1,GB1,1)) | GE3: ="学年"&GE$1 -> 学年423 | GF3: =IF(OFFSET(Gemini抽出データ!$A$1,GE1,1)=0,"",OFFSET(Gemini抽出データ!$A$1,GE1,1)) | GH3: ="学年"&GH$1 -> 学年424 | GI3: =IF(OFFSET(Gemini抽出データ!$A$1,GH1,1)=0,"",OFFSET(Gemini抽出データ!$A$1,GH1,1)) | GK3: ="種類"&GK$1 -> 種類449 | GL3: =IF(OFFSET(Gemini抽出データ!$A$1,GK1,1)=0,"",OFFSET(Gemini抽出データ!$A$1,GK1,1)) | GN3: ="学年"&GN$1 -> 学年450 | GO3: =IF(OFFSET(Gemini抽出データ!$A$1,GN1,1)=0,"",OFFSET(Gemini抽出データ!$A$1,GN1,1)) | GQ3: ="学年"&GQ$1 -> 学年451 | GR3: =IF(OFFSET(Gemini抽出データ!$A$1,GQ1,1)=0,"",OFFSET(Gemini抽出データ!$A$1,GQ1,1)) | GT3: ="学年"&GT$1 -> 学年452 | GU3: =IF(OFFSET(Gemini抽出データ!$A$1,GT1,1)=0,"",OFFSET(Gemini抽出データ!$A$1,GT1,1)) | GW3: ="種類"&GW$1 -> 種類477 | GX3: =IF(OFFSET(Gemini抽出データ!$A$1,GW1,1)=0,"",OFFSET(Gemini抽出データ!$A$1,GW1,1)) | GZ3: ="学年"&GZ$1 -> 学年478 | HA3: =IF(OFFSET(Gemini抽出データ!$A$1,GZ1,1)=0,"",OFFSET(Gemini抽出データ!$A$1,GZ1,1)) | HC3: ="学年"&HC$1 -> 学年479 | HD3: =IF(OFFSET(Gemini抽出データ!$A$1,HC1,1)=0,"",OFFSET(Gemini抽出データ!$A$1,HC1,1)) | HF3: ="学年"&HF$1 -> 学年480 | HG3: =IF(OFFSET(Gemini抽出データ!$A$1,HF1,1)=0,"",OFFSET(Gemini抽出データ!$A$1,HF1,1)) | HI3: ="種類"&HI$1 -> 種類505 | HJ3: =IF(OFFSET(Gemini抽出データ!$A$1,HI1,1)=0,"",OFFSET(Gemini抽出データ!$A$1,HI1,1)) | HL3: ="学年"&HL$1 -> 学年506 | HM3: =IF(OFFSET(Gemini抽出データ!$A$1,HL1,1)=0,"",OFFSET(Gemini抽出データ!$A$1,HL1,1)) | HO3: ="学年"&HO$1 -> 学年507 | HP3: =IF(OFFSET(Gemini抽出データ!$A$1,HO1,1)=0,"",OFFSET(Gemini抽出データ!$A$1,HO1,1)) | HR3: ="学年"&HR$1 -> 学年508 | HS3: =IF(OFFSET(Gemini抽出データ!$A$1,HR1,1)=0,"",OFFSET(Gemini抽出データ!$A$1,HR1,1)) | HU3: =IF(OFFSET(Gemini抽出データ!$A$1,#REF!,1)=0,"",OFFSET(Gemini抽出データ!$A$1,#REF!,1)) -> #REF!
A4: ="学年"&A$1 -> 学年1 | M4: ="学年"&M$1 -> 学年29 | Y4: ="学年"&Y$1 -> 学年57 | AK4: ="学年"&AK$1 -> 学年85 | AW4: ="学年"&AW$1 -> 学年113 | BI4: ="学年"&BI$1 -> 学年141 | BU4: ="学年"&BU$1 -> 学年169 | CG4: ="学年"&CG$1 -> 学年197 | CS4: ="学年"&CS$1 -> 学年225 | DE4: ="学年"&DE$1 -> 学年253 | DQ4: ="学年"&DQ$1 -> 学年281 | EC4: ="学年"&EC$1 -> 学年309 | EO4: ="学年"&EO$1 -> 学年337 | FA4: ="学年"&FA$1 -> 学年365 | FM4: ="学年"&FM$1 -> 学年393 | FY4: ="学年"&FY$1 -> 学年421 | GK4: ="学年"&GK$1 -> 学年449 | GW4: ="学年"&GW$1 -> 学年477 | HI4: ="学年"&HI$1 -> 学年505
B5: =OFFSET(Gemini抽出データ!$A$1,A1,3) -> 0 | E5: =OFFSET(Gemini抽出データ!$A$1,D1,3) -> 0 | H5: =OFFSET(Gemini抽出データ!$A$1,G1,3) -> 0 | K5: =OFFSET(Gemini抽出データ!$A$1,J1,3) -> 0 | N5: =OFFSET(Gemini抽出データ!$A$1,M1,3) -> 0 | Q5: =OFFSET(Gemini抽出データ!$A$1,P1,3) -> 0 | T5: =OFFSET(Gemini抽出データ!$A$1,S1,3) -> 0 | W5: =OFFSET(Gemini抽出データ!$A$1,V1,3) -> 0 | Z5: =OFFSET(Gemini抽出データ!$A$1,Y1,3) -> 0 | AC5: =OFFSET(Gemini抽出データ!$A$1,AB1,3) -> 0 | AF5: =OFFSET(Gemini抽出データ!$A$1,AE1,3) -> 0 | AI5: =OFFSET(Gemini抽出データ!$A$1,AH1,3) -> 0 | AL5: =OFFSET(Gemini抽出データ!$A$1,AK1,3) -> 0 | AO5: =OFFSET(Gemini抽出データ!$A$1,AN1,3) -> 0 | AR5: =OFFSET(Gemini抽出データ!$A$1,AQ1,3) -> 0 | AU5: =OFFSET(Gemini抽出データ!$A$1,AT1,3) -> 0 | AX5: =OFFSET(Gemini抽出データ!$A$1,AW1,3) -> 0 | BA5: =OFFSET(Gemini抽出データ!$A$1,AZ1,3) -> 0 | BD5: =OFFSET(Gemini抽出データ!$A$1,BC1,3) -> 0 | BG5: =OFFSET(Gemini抽出データ!$A$1,BF1,3) -> 0 | BJ5: =OFFSET(Gemini抽出データ!$A$1,BI1,3) -> 0 | BM5: =OFFSET(Gemini抽出データ!$A$1,BL1,3) -> 0 | BP5: =OFFSET(Gemini抽出データ!$A$1,BO1,3) -> 0 | BS5: =OFFSET(Gemini抽出データ!$A$1,BR1,3) -> 0 | BV5: =OFFSET(Gemini抽出データ!$A$1,BU1,3) -> 0 | BY5: =OFFSET(Gemini抽出データ!$A$1,BX1,3) -> 0 | CB5: =OFFSET(Gemini抽出データ!$A$1,CA1,3) -> 0 | CE5: =OFFSET(Gemini抽出データ!$A$1,CD1,3) -> 0 | CH5: =OFFSET(Gemini抽出データ!$A$1,CG1,3) -> 0 | CK5: =OFFSET(Gemini抽出データ!$A$1,CJ1,3) -> 0 | CN5: =OFFSET(Gemini抽出データ!$A$1,CM1,3) -> 0 | CQ5: =OFFSET(Gemini抽出データ!$A$1,CP1,3) -> 0 | CT5: =OFFSET(Gemini抽出データ!$A$1,CS1,3) -> 0 | CW5: =OFFSET(Gemini抽出データ!$A$1,CV1,3) -> 0 | CZ5: =OFFSET(Gemini抽出データ!$A$1,CY1,3) -> 0 | DC5: =OFFSET(Gemini抽出データ!$A$1,DB1,3) -> 0 | DF5: =OFFSET(Gemini抽出データ!$A$1,DE1,3) -> 0 | DI5: =OFFSET(Gemini抽出データ!$A$1,DH1,3) -> 0 | DL5: =OFFSET(Gemini抽出データ!$A$1,DK1,3) -> 0 | DO5: =OFFSET(Gemini抽出データ!$A$1,DN1,3) -> 0 | DR5: =OFFSET(Gemini抽出データ!$A$1,DQ1,3) -> 0 | DU5: =OFFSET(Gemini抽出データ!$A$1,DT1,3) -> 0 | DX5: =OFFSET(Gemini抽出データ!$A$1,DW1,3) -> 0 | EA5: =OFFSET(Gemini抽出データ!$A$1,DZ1,3) -> 0 | ED5: =OFFSET(Gemini抽出データ!$A$1,EC1,3) -> 0 | EG5: =OFFSET(Gemini抽出データ!$A$1,EF1,3) -> 0 | EJ5: =OFFSET(Gemini抽出データ!$A$1,EI1,3) -> 0 | EM5: =OFFSET(Gemini抽出データ!$A$1,EL1,3) -> 0 | EP5: =OFFSET(Gemini抽出データ!$A$1,EO1,3) -> 0 | ES5: =OFFSET(Gemini抽出データ!$A$1,ER1,3) -> 0 | EV5: =OFFSET(Gemini抽出データ!$A$1,EU1,3) -> 0 | EY5: =OFFSET(Gemini抽出データ!$A$1,EX1,3) -> 0 | FB5: =OFFSET(Gemini抽出データ!$A$1,FA1,3) -> 0 | FE5: =OFFSET(Gemini抽出データ!$A$1,FD1,3) -> 0 | FH5: =OFFSET(Gemini抽出データ!$A$1,FG1,3) -> 0 | FK5: =OFFSET(Gemini抽出データ!$A$1,FJ1,3) -> 0 | FN5: =OFFSET(Gemini抽出データ!$A$1,FM1,3) -> 0 | FQ5: =OFFSET(Gemini抽出データ!$A$1,FP1,3) -> 0 | FT5: =OFFSET(Gemini抽出データ!$A$1,FS1,3) -> 0 | FW5: =OFFSET(Gemini抽出データ!$A$1,FV1,3) -> 0 | FZ5: =OFFSET(Gemini抽出データ!$A$1,FY1,3) -> 0 | GC5: =OFFSET(Gemini抽出データ!$A$1,GB1,3) -> 0 | GF5: =OFFSET(Gemini抽出データ!$A$1,GE1,3) -> 0 | GI5: =OFFSET(Gemini抽出データ!$A$1,GH1,3) -> 0 | GL5: =OFFSET(Gemini抽出データ!$A$1,GK1,3) -> 0 | GO5: =OFFSET(Gemini抽出データ!$A$1,GN1,3) -> 0 | GR5: =OFFSET(Gemini抽出データ!$A$1,GQ1,3) -> 0 | GU5: =OFFSET(Gemini抽出データ!$A$1,GT1,3) -> 0 | GX5: =OFFSET(Gemini抽出データ!$A$1,GW1,3) -> 0 | HA5: =OFFSET(Gemini抽出データ!$A$1,GZ1,3) -> 0 | HD5: =OFFSET(Gemini抽出データ!$A$1,HC1,3) -> 0 | HG5: =OFFSET(Gemini抽出データ!$A$1,HF1,3) -> 0 | HJ5: =OFFSET(Gemini抽出データ!$A$1,HI1,3) -> 0 | HM5: =OFFSET(Gemini抽出データ!$A$1,HL1,3) -> 0 | HP5: =OFFSET(Gemini抽出データ!$A$1,HO1,3) -> 0 | HS5: =OFFSET(Gemini抽出データ!$A$1,HR1,3) -> 0 | HU5: =OFFSET(Gemini抽出データ!$A$1,#REF!,3) -> #REF!
D6: ="クラス"&D$1 -> クラス2 | G6: ="クラス"&G$1 -> クラス3 | J6: ="クラス"&J$1 -> クラス4 | P6: ="クラス"&P$1 -> クラス30 | S6: ="クラス"&S$1 -> クラス31 | V6: ="クラス"&V$1 -> クラス32 | AB6: ="クラス"&AB$1 -> クラス58 | AE6: ="クラス"&AE$1 -> クラス59 | AH6: ="クラス"&AH$1 -> クラス60 | AN6: ="クラス"&AN$1 -> クラス86 | AQ6: ="クラス"&AQ$1 -> クラス87 | AT6: ="クラス"&AT$1 -> クラス88 | AZ6: ="クラス"&AZ$1 -> クラス114 | BC6: ="クラス"&BC$1 -> クラス115 | BF6: ="クラス"&BF$1 -> クラス116 | BL6: ="クラス"&BL$1 -> クラス142 | BO6: ="クラス"&BO$1 -> クラス143 | BR6: ="クラス"&BR$1 -> クラス144 | BX6: ="クラス"&BX$1 -> クラス170 | CA6: ="クラス"&CA$1 -> クラス171 | CD6: ="クラス"&CD$1 -> クラス172 | CJ6: ="クラス"&CJ$1 -> クラス198 | CM6: ="クラス"&CM$1 -> クラス199 | CP6: ="クラス"&CP$1 -> クラス200 | CV6: ="クラス"&CV$1 -> クラス226 | CY6: ="クラス"&CY$1 -> クラス227 | DB6: ="クラス"&DB$1 -> クラス228 | DH6: ="クラス"&DH$1 -> クラス254 | DK6: ="クラス"&DK$1 -> クラス255 | DN6: ="クラス"&DN$1 -> クラス256 | DT6: ="クラス"&DT$1 -> クラス282 | DW6: ="クラス"&DW$1 -> クラス283 | DZ6: ="クラス"&DZ$1 -> クラス284 | EF6: ="クラス"&EF$1 -> クラス310 | EI6: ="クラス"&EI$1 -> クラス311 | EL6: ="クラス"&EL$1 -> クラス312 | ER6: ="クラス"&ER$1 -> クラス338 | EU6: ="クラス"&EU$1 -> クラス339 | EX6: ="クラス"&EX$1 -> クラス340 | FD6: ="クラス"&FD$1 -> クラス366 | FG6: ="クラス"&FG$1 -> クラス367 | FJ6: ="クラス"&FJ$1 -> クラス368 | FP6: ="クラス"&FP$1 -> クラス394 | FS6: ="クラス"&FS$1 -> クラス395 | FV6: ="クラス"&FV$1 -> クラス396 | GB6: ="クラス"&GB$1 -> クラス422 | GE6: ="クラス"&GE$1 -> クラス423 | GH6: ="クラス"&GH$1 -> クラス424 | GN6: ="クラス"&GN$1 -> クラス450 | GQ6: ="クラス"&GQ$1 -> クラス451 | GT6: ="クラス"&GT$1 -> クラス452 | GZ6: ="クラス"&GZ$1 -> クラス478 | HC6: ="クラス"&HC$1 -> クラス479 | HF6: ="クラス"&HF$1 -> クラス480 | HL6: ="クラス"&HL$1 -> クラス506 | HO6: ="クラス"&HO$1 -> クラス507 | HR6: ="クラス"&HR$1 -> クラス508
B7: =OFFSET(Gemini抽出データ!$A$1,A1,4) -> 0 | C7: =IF(OFFSET(Gemini抽出データ!$A$1,A1,5)=0,"",OFFSET(Gemini抽出データ!$A$1,A1,5)) | D7: =A7 -> 0 | E7: =OFFSET(Gemini抽出データ!$A$1,D1,4) -> 0 | F7: =IF(OFFSET(Gemini抽出データ!$A$1,D1,5)=0,"",OFFSET(Gemini抽出データ!$A$1,D1,5)) | G7: =A7 -> 0 | H7: =OFFSET(Gemini抽出データ!$A$1,G1,4) -> 0 | I7: =IF(OFFSET(Gemini抽出データ!$A$1,G1,5)=0,"",OFFSET(Gemini抽出データ!$A$1,G1,5)) | J7: =G7 -> 0 | K7: =OFFSET(Gemini抽出データ!$A$1,J1,4) -> 0 | L7: =IF(OFFSET(Gemini抽出データ!$A$1,J1,5)=0,"",OFFSET(Gemini抽出データ!$A$1,J1,5)) | N7: =OFFSET(Gemini抽出データ!$A$1,M1,4) -> 0 | O7: =IF(OFFSET(Gemini抽出データ!$A$1,M1,5)=0,"",OFFSET(Gemini抽出データ!$A$1,M1,5)) | P7: =M7 -> 0 | Q7: =OFFSET(Gemini抽出データ!$A$1,P1,4) -> 0 | R7: =IF(OFFSET(Gemini抽出データ!$A$1,P1,5)=0,"",OFFSET(Gemini抽出データ!$A$1,P1,5)) | S7: =M7 -> 0 | T7: =OFFSET(Gemini抽出データ!$A$1,S1,4) -> 0 | U7: =IF(OFFSET(Gemini抽出データ!$A$1,S1,5)=0,"",OFFSET(Gemini抽出データ!$A$1,S1,5)) | V7: =S7 -> 0 | W7: =OFFSET(Gemini抽出データ!$A$1,V1,4) -> 0 | X7: =IF(OFFSET(Gemini抽出データ!$A$1,V1,5)=0,"",OFFSET(Gemini抽出データ!$A$1,V1,5)) | Z7: =OFFSET(Gemini抽出データ!$A$1,Y1,4) -> 0 | AA7: =IF(OFFSET(Gemini抽出データ!$A$1,Y1,5)=0,"",OFFSET(Gemini抽出データ!$A$1,Y1,5)) | AB7: =Y7 -> 0 | AC7: =OFFSET(Gemini抽出データ!$A$1,AB1,4) -> 0 | AD7: =IF(OFFSET(Gemini抽出データ!$A$1,AB1,5)=0,"",OFFSET(Gemini抽出データ!$A$1,AB1,5)) | AE7: =Y7 -> 0 | AF7: =OFFSET(Gemini抽出データ!$A$1,AE1,4) -> 0 | AG7: =IF(OFFSET(Gemini抽出データ!$A$1,AE1,5)=0,"",OFFSET(Gemini抽出データ!$A$1,AE1,5)) | AH7: =AE7 -> 0 | AI7: =OFFSET(Gemini抽出データ!$A$1,AH1,4) -> 0 | AJ7: =IF(OFFSET(Gemini抽出データ!$A$1,AH1,5)=0,"",OFFSET(Gemini抽出データ!$A$1,AH1,5)) | AL7: =OFFSET(Gemini抽出データ!$A$1,AK1,4) -> 0 | AM7: =IF(OFFSET(Gemini抽出データ!$A$1,AK1,5)=0,"",OFFSET(Gemini抽出データ!$A$1,AK1,5)) | AN7: =AK7 -> 0 | AO7: =OFFSET(Gemini抽出データ!$A$1,AN1,4) -> 0 | AP7: =IF(OFFSET(Gemini抽出データ!$A$1,AN1,5)=0,"",OFFSET(Gemini抽出データ!$A$1,AN1,5)) | AQ7: =AK7 -> 0 | AR7: =OFFSET(Gemini抽出データ!$A$1,AQ1,4) -> 0 | AS7: =IF(OFFSET(Gemini抽出データ!$A$1,AQ1,5)=0,"",OFFSET(Gemini抽出データ!$A$1,AQ1,5)) | AT7: =AQ7 -> 0 | AU7: =OFFSET(Gemini抽出データ!$A$1,AT1,4) -> 0 | AV7: =IF(OFFSET(Gemini抽出データ!$A$1,AT1,5)=0,"",OFFSET(Gemini抽出データ!$A$1,AT1,5)) | AX7: =OFFSET(Gemini抽出データ!$A$1,AW1,4) -> 0 | AY7: =IF(OFFSET(Gemini抽出データ!$A$1,AW1,5)=0,"",OFFSET(Gemini抽出データ!$A$1,AW1,5)) | AZ7: =AW7 -> 0 | BA7: =OFFSET(Gemini抽出データ!$A$1,AZ1,4) -> 0 | BB7: =IF(OFFSET(Gemini抽出データ!$A$1,AZ1,5)=0,"",OFFSET(Gemini抽出データ!$A$1,AZ1,5)) | BC7: =AW7 -> 0 | BD7: =OFFSET(Gemini抽出データ!$A$1,BC1,4) -> 0 | BE7: =IF(OFFSET(Gemini抽出データ!$A$1,BC1,5)=0,"",OFFSET(Gemini抽出データ!$A$1,BC1,5)) | BF7: =BC7 -> 0 | BG7: =OFFSET(Gemini抽出データ!$A$1,BF1,4) -> 0 | BH7: =IF(OFFSET(Gemini抽出データ!$A$1,BF1,5)=0,"",OFFSET(Gemini抽出データ!$A$1,BF1,5)) | BJ7: =OFFSET(Gemini抽出データ!$A$1,BI1,4) -> 0 | BK7: =IF(OFFSET(Gemini抽出データ!$A$1,BI1,5)=0,"",OFFSET(Gemini抽出データ!$A$1,BI1,5)) | BL7: =BI7 -> 0 | BM7: =OFFSET(Gemini抽出データ!$A$1,BL1,4) -> 0 | BN7: =IF(OFFSET(Gemini抽出データ!$A$1,BL1,5)=0,"",OFFSET(Gemini抽出データ!$A$1,BL1,5)) | BO7: =BI7 -> 0 | BP7: =OFFSET(Gemini抽出データ!$A$1,BO1,4) -> 0 | BQ7: =IF(OFFSET(Gemini抽出データ!$A$1,BO1,5)=0,"",OFFSET(Gemini抽出データ!$A$1,BO1,5)) | BR7: =BO7 -> 0 | BS7: =OFFSET(Gemini抽出データ!$A$1,BR1,4) -> 0 | BT7: =IF(OFFSET(Gemini抽出データ!$A$1,BR1,5)=0,"",OFFSET(Gemini抽出データ!$A$1,BR1,5)) | BV7: =OFFSET(Gemini抽出データ!$A$1,BU1,4) -> 0 | BW7: =IF(OFFSET(Gemini抽出データ!$A$1,BU1,5)=0,"",OFFSET(Gemini抽出データ!$A$1,BU1,5)) | BX7: =BU7 -> 0 | BY7: =OFFSET(Gemini抽出データ!$A$1,BX1,4) -> 0 | BZ7: =IF(OFFSET(Gemini抽出データ!$A$1,BX1,5)=0,"",OFFSET(Gemini抽出データ!$A$1,BX1,5)) | CA7: =BU7 -> 0 | CB7: =OFFSET(Gemini抽出データ!$A$1,CA1,4) -> 0 | CC7: =IF(OFFSET(Gemini抽出データ!$A$1,CA1,5)=0,"",OFFSET(Gemini抽出データ!$A$1,CA1,5)) | CD7: =CA7 -> 0 | CE7: =OFFSET(Gemini抽出データ!$A$1,CD1,4) -> 0 | CF7: =IF(OFFSET(Gemini抽出データ!$A$1,CD1,5)=0,"",OFFSET(Gemini抽出データ!$A$1,CD1,5)) | CH7: =OFFSET(Gemini抽出データ!$A$1,CG1,4) -> 0 | CI7: =IF(OFFSET(Gemini抽出データ!$A$1,CG1,5)=0,"",OFFSET(Gemini抽出データ!$A$1,CG1,5)) | CJ7: =CG7 -> 0 | CK7: =OFFSET(Gemini抽出データ!$A$1,CJ1,4) -> 0 | CL7: =IF(OFFSET(Gemini抽出データ!$A$1,CJ1,5)=0,"",OFFSET(Gemini抽出データ!$A$1,CJ1,5)) | CM7: =CG7 -> 0 | CN7: =OFFSET(Gemini抽出データ!$A$1,CM1,4) -> 0 | CO7: =IF(OFFSET(Gemini抽出データ!$A$1,CM1,5)=0,"",OFFSET(Gemini抽出データ!$A$1,CM1,5)) | CP7: =CM7 -> 0 | CQ7: =OFFSET(Gemini抽出データ!$A$1,CP1,4) -> 0 | CR7: =IF(OFFSET(Gemini抽出データ!$A$1,CP1,5)=0,"",OFFSET(Gemini抽出データ!$A$1,CP1,5)) | CT7: =OFFSET(Gemini抽出データ!$A$1,CS1,4) -> 0 | CU7: =IF(OFFSET(Gemini抽出データ!$A$1,CS1,5)=0,"",OFFSET(Gemini抽出データ!$A$1,CS1,5)) | CV7: =CS7 -> 0 | CW7: =OFFSET(Gemini抽出データ!$A$1,CV1,4) -> 0 | CX7: =IF(OFFSET(Gemini抽出データ!$A$1,CV1,5)=0,"",OFFSET(Gemini抽出データ!$A$1,CV1,5)) | CY7: =CS7 -> 0 | CZ7: =OFFSET(Gemini抽出データ!$A$1,CY1,4) -> 0 | DA7: =IF(OFFSET(Gemini抽出データ!$A$1,CY1,5)=0,"",OFFSET(Gemini抽出データ!$A$1,CY1,5)) | DB7: =CY7 -> 0 | DC7: =OFFSET(Gemini抽出データ!$A$1,DB1,4) -> 0 | DD7: =IF(OFFSET(Gemini抽出データ!$A$1,DB1,5)=0,"",OFFSET(Gemini抽出データ!$A$1,DB1,5)) | DF7: =OFFSET(Gemini抽出データ!$A$1,DE1,4) -> 0 | DG7: =IF(OFFSET(Gemini抽出データ!$A$1,DE1,5)=0,"",OFFSET(Gemini抽出データ!$A$1,DE1,5)) | DH7: =DE7 -> 0 | DI7: =OFFSET(Gemini抽出データ!$A$1,DH1,4) -> 0 | DJ7: =IF(OFFSET(Gemini抽出データ!$A$1,DH1,5)=0,"",OFFSET(Gemini抽出データ!$A$1,DH1,5)) | DK7: =DE7 -> 0 | DL7: =OFFSET(Gemini抽出データ!$A$1,DK1,4) -> 0 | DM7: =IF(OFFSET(Gemini抽出データ!$A$1,DK1,5)=0,"",OFFSET(Gemini抽出データ!$A$1,DK1,5)) | DN7: =DK7 -> 0 | DO7: =OFFSET(Gemini抽出データ!$A$1,DN1,4) -> 0 | DP7: =IF(OFFSET(Gemini抽出データ!$A$1,DN1,5)=0,"",OFFSET(Gemini抽出データ!$A$1,DN1,5)) | DR7: =OFFSET(Gemini抽出データ!$A$1,DQ1,4) -> 0 | DS7: =IF(OFFSET(Gemini抽出データ!$A$1,DQ1,5)=0,"",OFFSET(Gemini抽出データ!$A$1,DQ1,5)) | DT7: =DQ7 -> 0 | DU7: =OFFSET(Gemini抽出データ!$A$1,DT1,4) -> 0 | DV7: =IF(OFFSET(Gemini抽出データ!$A$1,DT1,5)=0,"",OFFSET(Gemini抽出データ!$A$1,DT1,5)) | DW7: =DQ7 -> 0 | DX7: =OFFSET(Gemini抽出データ!$A$1,DW1,4) -> 0 | DY7: =IF(OFFSET(Gemini抽出データ!$A$1,DW1,5)=0,"",OFFSET(Gemini抽出データ!$A$1,DW1,5)) | DZ7: =DW7 -> 0 | EA7: =OFFSET(Gemini抽出データ!$A$1,DZ1,4) -> 0 | EB7: =IF(OFFSET(Gemini抽出データ!$A$1,DZ1,5)=0,"",OFFSET(Gemini抽出データ!$A$1,DZ1,5)) | ED7: =OFFSET(Gemini抽出データ!$A$1,EC1,4) -> 0 | EE7: =IF(OFFSET(Gemini抽出データ!$A$1,EC1,5)=0,"",OFFSET(Gemini抽出データ!$A$1,EC1,5)) | EF7: =EC7 -> 0 | EG7: =OFFSET(Gemini抽出データ!$A$1,EF1,4) -> 0 | EH7: =IF(OFFSET(Gemini抽出データ!$A$1,EF1,5)=0,"",OFFSET(Gemini抽出データ!$A$1,EF1,5)) | EI7: =EC7 -> 0 | EJ7: =OFFSET(Gemini抽出データ!$A$1,EI1,4) -> 0 | EK7: =IF(OFFSET(Gemini抽出データ!$A$1,EI1,5)=0,"",OFFSET(Gemini抽出データ!$A$1,EI1,5)) | EL7: =EI7 -> 0 | EM7: =OFFSET(Gemini抽出データ!$A$1,EL1,4) -> 0 | EN7: =IF(OFFSET(Gemini抽出データ!$A$1,EL1,5)=0,"",OFFSET(Gemini抽出データ!$A$1,EL1,5)) | EP7: =OFFSET(Gemini抽出データ!$A$1,EO1,4) -> 0 | EQ7: =IF(OFFSET(Gemini抽出データ!$A$1,EO1,5)=0,"",OFFSET(Gemini抽出データ!$A$1,EO1,5)) | ER7: =EO7 -> 0 | ES7: =OFFSET(Gemini抽出データ!$A$1,ER1,4) -> 0 | ET7: =IF(OFFSET(Gemini抽出データ!$A$1,ER1,5)=0,"",OFFSET(Gemini抽出データ!$A$1,ER1,5)) | EU7: =EO7 -> 0 | EV7: =OFFSET(Gemini抽出データ!$A$1,EU1,4) -> 0 | EW7: =IF(OFFSET(Gemini抽出データ!$A$1,EU1,5)=0,"",OFFSET(Gemini抽出データ!$A$1,EU1,5)) | EX7: =EU7 -> 0 | EY7: =OFFSET(Gemini抽出データ!$A$1,EX1,4) -> 0 | EZ7: =IF(OFFSET(Gemini抽出データ!$A$1,EX1,5)=0,"",OFFSET(Gemini抽出データ!$A$1,EX1,5)) | FB7: =OFFSET(Gemini抽出データ!$A$1,FA1,4) -> 0 | FC7: =IF(OFFSET(Gemini抽出データ!$A$1,FA1,5)=0,"",OFFSET(Gemini抽出データ!$A$1,FA1,5)) | FD7: =FA7 -> 0 | FE7: =OFFSET(Gemini抽出データ!$A$1,FD1,4) -> 0 | FF7: =IF(OFFSET(Gemini抽出データ!$A$1,FD1,5)=0,"",OFFSET(Gemini抽出データ!$A$1,FD1,5)) | FG7: =FA7 -> 0 | FH7: =OFFSET(Gemini抽出データ!$A$1,FG1,4) -> 0 | FI7: =IF(OFFSET(Gemini抽出データ!$A$1,FG1,5)=0,"",OFFSET(Gemini抽出データ!$A$1,FG1,5)) | FJ7: =FG7 -> 0 | FK7: =OFFSET(Gemini抽出データ!$A$1,FJ1,4) -> 0 | FL7: =IF(OFFSET(Gemini抽出データ!$A$1,FJ1,5)=0,"",OFFSET(Gemini抽出データ!$A$1,FJ1,5)) | FN7: =OFFSET(Gemini抽出データ!$A$1,FM1,4) -> 0 | FO7: =IF(OFFSET(Gemini抽出データ!$A$1,FM1,5)=0,"",OFFSET(Gemini抽出データ!$A$1,FM1,5)) | FP7: =FM7 -> 0 | FQ7: =OFFSET(Gemini抽出データ!$A$1,FP1,4) -> 0 | FR7: =IF(OFFSET(Gemini抽出データ!$A$1,FP1,5)=0,"",OFFSET(Gemini抽出データ!$A$1,FP1,5)) | FS7: =FM7 -> 0 | FT7: =OFFSET(Gemini抽出データ!$A$1,FS1,4) -> 0 | FU7: =IF(OFFSET(Gemini抽出データ!$A$1,FS1,5)=0,"",OFFSET(Gemini抽出データ!$A$1,FS1,5)) | FV7: =FS7 -> 0 | FW7: =OFFSET(Gemini抽出データ!$A$1,FV1,4) -> 0 | FX7: =IF(OFFSET(Gemini抽出データ!$A$1,FV1,5)=0,"",OFFSET(Gemini抽出データ!$A$1,FV1,5)) | FZ7: =OFFSET(Gemini抽出データ!$A$1,FY1,4) -> 0 | GA7: =IF(OFFSET(Gemini抽出データ!$A$1,FY1,5)=0,"",OFFSET(Gemini抽出データ!$A$1,FY1,5)) | GB7: =FY7 -> 0 | GC7: =OFFSET(Gemini抽出データ!$A$1,GB1,4) -> 0 | GD7: =IF(OFFSET(Gemini抽出データ!$A$1,GB1,5)=0,"",OFFSET(Gemini抽出データ!$A$1,GB1,5)) | GE7: =FY7 -> 0 | GF7: =OFFSET(Gemini抽出データ!$A$1,GE1,4) -> 0 | GG7: =IF(OFFSET(Gemini抽出データ!$A$1,GE1,5)=0,"",OFFSET(Gemini抽出データ!$A$1,GE1,5)) | GH7: =GE7 -> 0 | GI7: =OFFSET(Gemini抽出データ!$A$1,GH1,4) -> 0 | GJ7: =IF(OFFSET(Gemini抽出データ!$A$1,GH1,5)=0,"",OFFSET(Gemini抽出データ!$A$1,GH1,5)) | GL7: =OFFSET(Gemini抽出データ!$A$1,GK1,4) -> 0 | GM7: =IF(OFFSET(Gemini抽出データ!$A$1,GK1,5)=0,"",OFFSET(Gemini抽出データ!$A$1,GK1,5)) | GN7: =GK7 -> 0 | GO7: =OFFSET(Gemini抽出データ!$A$1,GN1,4) -> 0 | GP7: =IF(OFFSET(Gemini抽出データ!$A$1,GN1,5)=0,"",OFFSET(Gemini抽出データ!$A$1,GN1,5)) | GQ7: =GK7 -> 0 | GR7: =OFFSET(Gemini抽出データ!$A$1,GQ1,4) -> 0 | GS7: =IF(OFFSET(Gemini抽出データ!$A$1,GQ1,5)=0,"",OFFSET(Gemini抽出データ!$A$1,GQ1,5)) | GT7: =GQ7 -> 0 | GU7: =OFFSET(Gemini抽出データ!$A$1,GT1,4) -> 0 | GV7: =IF(OFFSET(Gemini抽出データ!$A$1,GT1,5)=0,"",OFFSET(Gemini抽出データ!$A$1,GT1,5)) | GX7: =OFFSET(Gemini抽出データ!$A$1,GW1,4) -> 0 | GY7: =IF(OFFSET(Gemini抽出データ!$A$1,GW1,5)=0,"",OFFSET(Gemini抽出データ!$A$1,GW1,5)) | GZ7: =GW7 -> 0 | HA7: =OFFSET(Gemini抽出データ!$A$1,GZ1,4) -> 0 | HB7: =IF(OFFSET(Gemini抽出データ!$A$1,GZ1,5)=0,"",OFFSET(Gemini抽出データ!$A$1,GZ1,5)) | HC7: =GW7 -> 0 | HD7: =OFFSET(Gemini抽出データ!$A$1,HC1,4) -> 0 | HE7: =IF(OFFSET(Gemini抽出データ!$A$1,HC1,5)=0,"",OFFSET(Gemini抽出データ!$A$1,HC1,5)) | HF7: =HC7 -> 0 | HG7: =OFFSET(Gemini抽出データ!$A$1,HF1,4) -> 0 | HH7: =IF(OFFSET(Gemini抽出データ!$A$1,HF1,5)=0,"",OFFSET(Gemini抽出データ!$A$1,HF1,5)) | HJ7: =OFFSET(Gemini抽出データ!$A$1,HI1,4) -> 0 | HK7: =IF(OFFSET(Gemini抽出データ!$A$1,HI1,5)=0,"",OFFSET(Gemini抽出データ!$A$1,HI1,5)) | HL7: =HI7 -> 0 | HM7: =OFFSET(Gemini抽出データ!$A$1,HL1,4) -> 0 | HN7: =IF(OFFSET(Gemini抽出データ!$A$1,HL1,5)=0,"",OFFSET(Gemini抽出データ!$A$1,HL1,5)) | HO7: =HI7 -> 0 | HP7: =OFFSET(Gemini抽出データ!$A$1,HO1,4) -> 0 | HQ7: =IF(OFFSET(Gemini抽出データ!$A$1,HO1,5)=0,"",OFFSET(Gemini抽出データ!$A$1,HO1,5)) | HR7: =HO7 -> 0 | HS7: =OFFSET(Gemini抽出データ!$A$1,HR1,4) -> 0 | HT7: =IF(OFFSET(Gemini抽出データ!$A$1,HR1,5)=0,"",OFFSET(Gemini抽出データ!$A$1,HR1,5)) | HU7: =OFFSET(Gemini抽出データ!$A$1,#REF!,4) -> #REF! | HV7: =IF(OFFSET(Gemini抽出データ!$A$1,#REF!,5)=0,"",OFFSET(Gemini抽出データ!$A$1,#REF!,5)) -> #REF!
A8: =J1+1 -> 5 | B8: =OFFSET(Gemini抽出データ!$A$1,A8,0) -> 0 | D8: =A8+1 -> 6 | E8: =OFFSET(Gemini抽出データ!$A$1,D8,0) -> 0 | G8: =D8+1 -> 7 | H8: =OFFSET(Gemini抽出データ!$A$1,G8,0) -> 0 | J8: =G8+1 -> 8 | K8: =OFFSET(Gemini抽出データ!$A$1,J8,0) -> 0 | M8: =V1+1 -> 33 | N8: =OFFSET(Gemini抽出データ!$A$1,M8,0) -> 0 | P8: =M8+1 -> 34 | Q8: =OFFSET(Gemini抽出データ!$A$1,P8,0) -> 0 | S8: =P8+1 -> 35 | T8: =OFFSET(Gemini抽出データ!$A$1,S8,0) -> 0 | V8: =S8+1 -> 36 | W8: =OFFSET(Gemini抽出データ!$A$1,V8,0) -> 0 | Y8: =AH1+1 -> 61 | Z8: =OFFSET(Gemini抽出データ!$A$1,Y8,0) -> 0 | AB8: =Y8+1 -> 62 | AC8: =OFFSET(Gemini抽出データ!$A$1,AB8,0) -> 0 | AE8: =AB8+1 -> 63 | AF8: =OFFSET(Gemini抽出データ!$A$1,AE8,0) -> 0 | AH8: =AE8+1 -> 64 | AI8: =OFFSET(Gemini抽出データ!$A$1,AH8,0) -> 0 | AK8: =AT1+1 -> 89 | AL8: =OFFSET(Gemini抽出データ!$A$1,AK8,0) -> 0 | AN8: =AK8+1 -> 90 | AO8: =OFFSET(Gemini抽出データ!$A$1,AN8,0) -> 0 | AQ8: =AN8+1 -> 91 | AR8: =OFFSET(Gemini抽出データ!$A$1,AQ8,0) -> 0 | AT8: =AQ8+1 -> 92 | AU8: =OFFSET(Gemini抽出データ!$A$1,AT8,0) -> 0 | AW8: =BF1+1 -> 117 | AX8: =OFFSET(Gemini抽出データ!$A$1,AW8,0) -> 0 | AZ8: =AW8+1 -> 118 | BA8: =OFFSET(Gemini抽出データ!$A$1,AZ8,0) -> 0 | BC8: =AZ8+1 -> 119 | BD8: =OFFSET(Gemini抽出データ!$A$1,BC8,0) -> 0 | BF8: =BC8+1 -> 120 | BG8: =OFFSET(Gemini抽出データ!$A$1,BF8,0) -> 0 | BI8: =BR1+1 -> 145 | BJ8: =OFFSET(Gemini抽出データ!$A$1,BI8,0) -> 0 | BL8: =BI8+1 -> 146 | BM8: =OFFSET(Gemini抽出データ!$A$1,BL8,0) -> 0 | BO8: =BL8+1 -> 147 | BP8: =OFFSET(Gemini抽出データ!$A$1,BO8,0) -> 0 | BR8: =BO8+1 -> 148 | BS8: =OFFSET(Gemini抽出データ!$A$1,BR8,0) -> 0 | BU8: =CD1+1 -> 173 | BV8: =OFFSET(Gemini抽出データ!$A$1,BU8,0) -> 0 | BX8: =BU8+1 -> 174 | BY8: =OFFSET(Gemini抽出データ!$A$1,BX8,0) -> 0 | CA8: =BX8+1 -> 175 | CB8: =OFFSET(Gemini抽出データ!$A$1,CA8,0) -> 0 | CD8: =CA8+1 -> 176 | CE8: =OFFSET(Gemini抽出データ!$A$1,CD8,0) -> 0 | CG8: =CP1+1 -> 201 | CH8: =OFFSET(Gemini抽出データ!$A$1,CG8,0) -> 0 | CJ8: =CG8+1 -> 202 | CK8: =OFFSET(Gemini抽出データ!$A$1,CJ8,0) -> 0 | CM8: =CJ8+1 -> 203 | CN8: =OFFSET(Gemini抽出データ!$A$1,CM8,0) -> 0 | CP8: =CM8+1 -> 204 | CQ8: =OFFSET(Gemini抽出データ!$A$1,CP8,0) -> 0 | CS8: =DB1+1 -> 229 | CT8: =OFFSET(Gemini抽出データ!$A$1,CS8,0) -> 0 | CV8: =CS8+1 -> 230 | CW8: =OFFSET(Gemini抽出データ!$A$1,CV8,0) -> 0 | CY8: =CV8+1 -> 231 | CZ8: =OFFSET(Gemini抽出データ!$A$1,CY8,0) -> 0 | DB8: =CY8+1 -> 232 | DC8: =OFFSET(Gemini抽出データ!$A$1,DB8,0) -> 0 | DE8: =DN1+1 -> 257 | DF8: =OFFSET(Gemini抽出データ!$A$1,DE8,0) -> 0 | DH8: =DE8+1 -> 258 | DI8: =OFFSET(Gemini抽出データ!$A$1,DH8,0) -> 0 | DK8: =DH8+1 -> 259 | DL8: =OFFSET(Gemini抽出データ!$A$1,DK8,0) -> 0 | DN8: =DK8+1 -> 260 | DO8: =OFFSET(Gemini抽出データ!$A$1,DN8,0) -> 0 | DQ8: =DZ1+1 -> 285 | DR8: =OFFSET(Gemini抽出データ!$A$1,DQ8,0) -> 0 | DT8: =DQ8+1 -> 286 | DU8: =OFFSET(Gemini抽出データ!$A$1,DT8,0) -> 0 | DW8: =DT8+1 -> 287 | DX8: =OFFSET(Gemini抽出データ!$A$1,DW8,0) -> 0 | DZ8: =DW8+1 -> 288 | EA8: =OFFSET(Gemini抽出データ!$A$1,DZ8,0) -> 0 | EC8: =EL1+1 -> 313 | ED8: =OFFSET(Gemini抽出データ!$A$1,EC8,0) -> 0 | EF8: =EC8+1 -> 314 | EG8: =OFFSET(Gemini抽出データ!$A$1,EF8,0) -> 0 | EI8: =EF8+1 -> 315 | EJ8: =OFFSET(Gemini抽出データ!$A$1,EI8,0) -> 0 | EL8: =EI8+1 -> 316 | EM8: =OFFSET(Gemini抽出データ!$A$1,EL8,0) -> 0 | EO8: =EX1+1 -> 341 | EP8: =OFFSET(Gemini抽出データ!$A$1,EO8,0) -> 0 | ER8: =EO8+1 -> 342 | ES8: =OFFSET(Gemini抽出データ!$A$1,ER8,0) -> 0 | EU8: =ER8+1 -> 343 | EV8: =OFFSET(Gemini抽出データ!$A$1,EU8,0) -> 0 | EX8: =EU8+1 -> 344 | EY8: =OFFSET(Gemini抽出データ!$A$1,EX8,0) -> 0 | FA8: =FJ1+1 -> 369 | FB8: =OFFSET(Gemini抽出データ!$A$1,FA8,0) -> 0 | FD8: =FA8+1 -> 370 | FE8: =OFFSET(Gemini抽出データ!$A$1,FD8,0) -> 0 | FG8: =FD8+1 -> 371 | FH8: =OFFSET(Gemini抽出データ!$A$1,FG8,0) -> 0 | FJ8: =FG8+1 -> 372 | FK8: =OFFSET(Gemini抽出データ!$A$1,FJ8,0) -> 0 | FM8: =FV1+1 -> 397 | FN8: =OFFSET(Gemini抽出データ!$A$1,FM8,0) -> 0 | FP8: =FM8+1 -> 398 | FQ8: =OFFSET(Gemini抽出データ!$A$1,FP8,0) -> 0 | FS8: =FP8+1 -> 399 | FT8: =OFFSET(Gemini抽出データ!$A$1,FS8,0) -> 0 | FV8: =FS8+1 -> 400 | FW8: =OFFSET(Gemini抽出データ!$A$1,FV8,0) -> 0 | FY8: =GH1+1 -> 425 | FZ8: =OFFSET(Gemini抽出データ!$A$1,FY8,0) -> 0 | GB8: =FY8+1 -> 426 | GC8: =OFFSET(Gemini抽出データ!$A$1,GB8,0) -> 0 | GE8: =GB8+1 -> 427 | GF8: =OFFSET(Gemini抽出データ!$A$1,GE8,0) -> 0 | GH8: =GE8+1 -> 428 | GI8: =OFFSET(Gemini抽出データ!$A$1,GH8,0) -> 0 | GK8: =GT1+1 -> 453 | GL8: =OFFSET(Gemini抽出データ!$A$1,GK8,0) -> 0 | GN8: =GK8+1 -> 454 | GO8: =OFFSET(Gemini抽出データ!$A$1,GN8,0) -> 0 | GQ8: =GN8+1 -> 455 | GR8: =OFFSET(Gemini抽出データ!$A$1,GQ8,0) -> 0 | GT8: =GQ8+1 -> 456 | GU8: =OFFSET(Gemini抽出データ!$A$1,GT8,0) -> 0 | GW8: =HF1+1 -> 481 | GX8: =OFFSET(Gemini抽出データ!$A$1,GW8,0) -> 0 | GZ8: =GW8+1 -> 482 | HA8: =OFFSET(Gemini抽出データ!$A$1,GZ8,0) -> 0 | HC8: =GZ8+1 -> 483 | HD8: =OFFSET(Gemini抽出データ!$A$1,HC8,0) -> 0 | HF8: =HC8+1 -> 484 | HG8: =OFFSET(Gemini抽出データ!$A$1,HF8,0) -> 0 | HI8: =HR1+1 -> 509 | HJ8: =OFFSET(Gemini抽出データ!$A$1,HI8,0) -> 0 | HL8: =HI8+1 -> 510 | HM8: =OFFSET(Gemini抽出データ!$A$1,HL8,0) -> 0 | HO8: =HL8+1 -> 511 | HP8: =OFFSET(Gemini抽出データ!$A$1,HO8,0) -> 0 | HR8: =HO8+1 -> 512 | HS8: =OFFSET(Gemini抽出データ!$A$1,HR8,0) -> 0 | HU8: =OFFSET(Gemini抽出データ!$A$1,#REF!,0) -> #REF!
A9: ="クライアント名"&A$1 -> クライアント名1 | B9: =OFFSET(Gemini抽出データ!$A$1,A8,2) -> 0 | D9: ="クライアント名"&D$1 -> クライアント名2 | E9: =OFFSET(Gemini抽出データ!$A$1,D8,2) -> 0 | G9: ="クライアント名"&G$1 -> クライアント名3 | H9: =OFFSET(Gemini抽出データ!$A$1,G8,2) -> 0 | J9: ="クライアント名"&J$1 -> クライアント名4 | K9: =OFFSET(Gemini抽出データ!$A$1,J8,2) -> 0 | M9: ="クライアント名"&M$1 -> クライアント名29 | N9: =OFFSET(Gemini抽出データ!$A$1,M8,2) -> 0 | P9: ="クライアント名"&P$1 -> クライアント名30 | Q9: =OFFSET(Gemini抽出データ!$A$1,P8,2) -> 0 | S9: ="クライアント名"&S$1 -> クライアント名31 | T9: =OFFSET(Gemini抽出データ!$A$1,S8,2) -> 0 | V9: ="クライアント名"&V$1 -> クライアント名32 | W9: =OFFSET(Gemini抽出データ!$A$1,V8,2) -> 0 | Y9: ="クライアント名"&Y$1 -> クライアント名57 | Z9: =OFFSET(Gemini抽出データ!$A$1,Y8,2) -> 0 | AB9: ="クライアント名"&AB$1 -> クライアント名58 | AC9: =OFFSET(Gemini抽出データ!$A$1,AB8,2) -> 0 | AE9: ="クライアント名"&AE$1 -> クライアント名59 | AF9: =OFFSET(Gemini抽出データ!$A$1,AE8,2) -> 0 | AH9: ="クライアント名"&AH$1 -> クライアント名60 | AI9: =OFFSET(Gemini抽出データ!$A$1,AH8,2) -> 0 | AK9: ="クライアント名"&AK$1 -> クライアント名85 | AL9: =OFFSET(Gemini抽出データ!$A$1,AK8,2) -> 0 | AN9: ="クライアント名"&AN$1 -> クライアント名86 | AO9: =OFFSET(Gemini抽出データ!$A$1,AN8,2) -> 0 | AQ9: ="クライアント名"&AQ$1 -> クライアント名87 | AR9: =OFFSET(Gemini抽出データ!$A$1,AQ8,2) -> 0 | AT9: ="クライアント名"&AT$1 -> クライアント名88 | AU9: =OFFSET(Gemini抽出データ!$A$1,AT8,2) -> 0 | AW9: ="クライアント名"&AW$1 -> クライアント名113 | AX9: =OFFSET(Gemini抽出データ!$A$1,AW8,2) -> 0 | AZ9: ="クライアント名"&AZ$1 -> クライアント名114 | BA9: =OFFSET(Gemini抽出データ!$A$1,AZ8,2) -> 0 | BC9: ="クライアント名"&BC$1 -> クライアント名115 | BD9: =OFFSET(Gemini抽出データ!$A$1,BC8,2) -> 0 | BF9: ="クライアント名"&BF$1 -> クライアント名116 | BG9: =OFFSET(Gemini抽出データ!$A$1,BF8,2) -> 0 | BI9: ="クライアント名"&BI$1 -> クライアント名141 | BJ9: =OFFSET(Gemini抽出データ!$A$1,BI8,2) -> 0 | BL9: ="クライアント名"&BL$1 -> クライアント名142 | BM9: =OFFSET(Gemini抽出データ!$A$1,BL8,2) -> 0 | BO9: ="クライアント名"&BO$1 -> クライアント名143 | BP9: =OFFSET(Gemini抽出データ!$A$1,BO8,2) -> 0 | BR9: ="クライアント名"&BR$1 -> クライアント名144 | BS9: =OFFSET(Gemini抽出データ!$A$1,BR8,2) -> 0 | BU9: ="クライアント名"&BU$1 -> クライアント名169 | BV9: =OFFSET(Gemini抽出データ!$A$1,BU8,2) -> 0 | BX9: ="クライアント名"&BX$1 -> クライアント名170 | BY9: =OFFSET(Gemini抽出データ!$A$1,BX8,2) -> 0 | CA9: ="クライアント名"&CA$1 -> クライアント名171 | CB9: =OFFSET(Gemini抽出データ!$A$1,CA8,2) -> 0 | CD9: ="クライアント名"&CD$1 -> クライアント名172 | CE9: =OFFSET(Gemini抽出データ!$A$1,CD8,2) -> 0 | CG9: ="クライアント名"&CG$1 -> クライアント名197 | CH9: =OFFSET(Gemini抽出データ!$A$1,CG8,2) -> 0 | CJ9: ="クライアント名"&CJ$1 -> クライアント名198 | CK9: =OFFSET(Gemini抽出データ!$A$1,CJ8,2) -> 0 | CM9: ="クライアント名"&CM$1 -> クライアント名199 | CN9: =OFFSET(Gemini抽出データ!$A$1,CM8,2) -> 0 | CP9: ="クライアント名"&CP$1 -> クライアント名200 | CQ9: =OFFSET(Gemini抽出データ!$A$1,CP8,2) -> 0 | CS9: ="クライアント名"&CS$1 -> クライアント名225 | CT9: =OFFSET(Gemini抽出データ!$A$1,CS8,2) -> 0 | CV9: ="クライアント名"&CV$1 -> クライアント名226 | CW9: =OFFSET(Gemini抽出データ!$A$1,CV8,2) -> 0 | CY9: ="クライアント名"&CY$1 -> クライアント名227 | CZ9: =OFFSET(Gemini抽出データ!$A$1,CY8,2) -> 0 | DB9: ="クライアント名"&DB$1 -> クライアント名228 | DC9: =OFFSET(Gemini抽出データ!$A$1,DB8,2) -> 0 | DE9: ="クライアント名"&DE$1 -> クライアント名253 | DF9: =OFFSET(Gemini抽出データ!$A$1,DE8,2) -> 0 | DH9: ="クライアント名"&DH$1 -> クライアント名254 | DI9: =OFFSET(Gemini抽出データ!$A$1,DH8,2) -> 0 | DK9: ="クライアント名"&DK$1 -> クライアント名255 | DL9: =OFFSET(Gemini抽出データ!$A$1,DK8,2) -> 0 | DN9: ="クライアント名"&DN$1 -> クライアント名256 | DO9: =OFFSET(Gemini抽出データ!$A$1,DN8,2) -> 0 | DQ9: ="クライアント名"&DQ$1 -> クライアント名281 | DR9: =OFFSET(Gemini抽出データ!$A$1,DQ8,2) -> 0 | DT9: ="クライアント名"&DT$1 -> クライアント名282 | DU9: =OFFSET(Gemini抽出データ!$A$1,DT8,2) -> 0 | DW9: ="クライアント名"&DW$1 -> クライアント名283 | DX9: =OFFSET(Gemini抽出データ!$A$1,DW8,2) -> 0 | DZ9: ="クライアント名"&DZ$1 -> クライアント名284 | EA9: =OFFSET(Gemini抽出データ!$A$1,DZ8,2) -> 0 | EC9: ="クライアント名"&EC$1 -> クライアント名309 | ED9: =OFFSET(Gemini抽出データ!$A$1,EC8,2) -> 0 | EF9: ="クライアント名"&EF$1 -> クライアント名310 | EG9: =OFFSET(Gemini抽出データ!$A$1,EF8,2) -> 0 | EI9: ="クライアント名"&EI$1 -> クライアント名311 | EJ9: =OFFSET(Gemini抽出データ!$A$1,EI8,2) -> 0 | EL9: ="クライアント名"&EL$1 -> クライアント名312 | EM9: =OFFSET(Gemini抽出データ!$A$1,EL8,2) -> 0 | EO9: ="クライアント名"&EO$1 -> クライアント名337 | EP9: =OFFSET(Gemini抽出データ!$A$1,EO8,2) -> 0 | ER9: ="クライアント名"&ER$1 -> クライアント名338 | ES9: =OFFSET(Gemini抽出データ!$A$1,ER8,2) -> 0 | EU9: ="クライアント名"&EU$1 -> クライアント名339 | EV9: =OFFSET(Gemini抽出データ!$A$1,EU8,2) -> 0 | EX9: ="クライアント名"&EX$1 -> クライアント名340 | EY9: =OFFSET(Gemini抽出データ!$A$1,EX8,2) -> 0 | FA9: ="クライアント名"&FA$1 -> クライアント名365 | FB9: =OFFSET(Gemini抽出データ!$A$1,FA8,2) -> 0 | FD9: ="クライアント名"&FD$1 -> クライアント名366 | FE9: =OFFSET(Gemini抽出データ!$A$1,FD8,2) -> 0 | FG9: ="クライアント名"&FG$1 -> クライアント名367 | FH9: =OFFSET(Gemini抽出データ!$A$1,FG8,2) -> 0 | FJ9: ="クライアント名"&FJ$1 -> クライアント名368 | FK9: =OFFSET(Gemini抽出データ!$A$1,FJ8,2) -> 0 | FM9: ="クライアント名"&FM$1 -> クライアント名393 | FN9: =OFFSET(Gemini抽出データ!$A$1,FM8,2) -> 0 | FP9: ="クライアント名"&FP$1 -> クライアント名394 | FQ9: =OFFSET(Gemini抽出データ!$A$1,FP8,2) -> 0 | FS9: ="クライアント名"&FS$1 -> クライアント名395 | FT9: =OFFSET(Gemini抽出データ!$A$1,FS8,2) -> 0 | FV9: ="クライアント名"&FV$1 -> クライアント名396 | FW9: =OFFSET(Gemini抽出データ!$A$1,FV8,2) -> 0 | FY9: ="クライアント名"&FY$1 -> クライアント名421 | FZ9: =OFFSET(Gemini抽出データ!$A$1,FY8,2) -> 0 | GB9: ="クライアント名"&GB$1 -> クライアント名422 | GC9: =OFFSET(Gemini抽出データ!$A$1,GB8,2) -> 0 | GE9: ="クライアント名"&GE$1 -> クライアント名423 | GF9: =OFFSET(Gemini抽出データ!$A$1,GE8,2) -> 0 | GH9: ="クライアント名"&GH$1 -> クライアント名424 | GI9: =OFFSET(Gemini抽出データ!$A$1,GH8,2) -> 0 | GK9: ="クライアント名"&GK$1 -> クライアント名449 | GL9: =OFFSET(Gemini抽出データ!$A$1,GK8,2) -> 0 | GN9: ="クライアント名"&GN$1 -> クライアント名450 | GO9: =OFFSET(Gemini抽出データ!$A$1,GN8,2) -> 0 | GQ9: ="クライアント名"&GQ$1 -> クライアント名451 | GR9: =OFFSET(Gemini抽出データ!$A$1,GQ8,2) -> 0 | GT9: ="クライアント名"&GT$1 -> クライアント名452 | GU9: =OFFSET(Gemini抽出データ!$A$1,GT8,2) -> 0 | GW9: ="クライアント名"&GW$1 -> クライアント名477 | GX9: =OFFSET(Gemini抽出データ!$A$1,GW8,2) -> 0 | GZ9: ="クライアント名"&GZ$1 -> クライアント名478 | HA9: =OFFSET(Gemini抽出データ!$A$1,GZ8,2) -> 0 | HC9: ="クライアント名"&HC$1 -> クライアント名479 | HD9: =OFFSET(Gemini抽出データ!$A$1,HC8,2) -> 0 | HF9: ="クライアント名"&HF$1 -> クライアント名480 | HG9: =OFFSET(Gemini抽出データ!$A$1,HF8,2) -> 0 | HI9: ="クライアント名"&HI$1 -> クライアント名505 | HJ9: =OFFSET(Gemini抽出データ!$A$1,HI8,2) -> 0 | HL9: ="クライアント名"&HL$1 -> クライアント名506 | HM9: =OFFSET(Gemini抽出データ!$A$1,HL8,2) -> 0 | HO9: ="クライアント名"&HO$1 -> クライアント名507 | HP9: =OFFSET(Gemini抽出データ!$A$1,HO8,2) -> 0 | HR9: ="クライアント名"&HR$1 -> クライアント名508 | HS9: =OFFSET(Gemini抽出データ!$A$1,HR8,2) -> 0 | HU9: =OFFSET(Gemini抽出データ!$A$1,#REF!,2) -> #REF!
A10: ="種類"&A$1 -> 種類1 | B10: =IF(OFFSET(Gemini抽出データ!$A$1,A8,1)=0,"",OFFSET(Gemini抽出データ!$A$1,A8,1)) | D10: ="学年"&D$1 -> 学年2 | E10: =IF(OFFSET(Gemini抽出データ!$A$1,D8,1)=0,"",OFFSET(Gemini抽出データ!$A$1,D8,1)) | G10: ="学年"&G$1 -> 学年3 | H10: =IF(OFFSET(Gemini抽出データ!$A$1,G8,1)=0,"",OFFSET(Gemini抽出データ!$A$1,G8,1)) | J10: ="学年"&J$1 -> 学年4 | K10: =IF(OFFSET(Gemini抽出データ!$A$1,J8,1)=0,"",OFFSET(Gemini抽出データ!$A$1,J8,1)) | M10: ="種類"&M$1 -> 種類29 | N10: =IF(OFFSET(Gemini抽出データ!$A$1,M8,1)=0,"",OFFSET(Gemini抽出データ!$A$1,M8,1)) | P10: ="学年"&P$1 -> 学年30 | Q10: =IF(OFFSET(Gemini抽出データ!$A$1,P8,1)=0,"",OFFSET(Gemini抽出データ!$A$1,P8,1)) | S10: ="学年"&S$1 -> 学年31 | T10: =IF(OFFSET(Gemini抽出データ!$A$1,S8,1)=0,"",OFFSET(Gemini抽出データ!$A$1,S8,1)) | V10: ="学年"&V$1 -> 学年32 | W10: =IF(OFFSET(Gemini抽出データ!$A$1,V8,1)=0,"",OFFSET(Gemini抽出データ!$A$1,V8,1)) | Y10: ="種類"&Y$1 -> 種類57 | Z10: =IF(OFFSET(Gemini抽出データ!$A$1,Y8,1)=0,"",OFFSET(Gemini抽出データ!$A$1,Y8,1)) | AB10: ="学年"&AB$1 -> 学年58 | AC10: =IF(OFFSET(Gemini抽出データ!$A$1,AB8,1)=0,"",OFFSET(Gemini抽出データ!$A$1,AB8,1)) | AE10: ="学年"&AE$1 -> 学年59 | AF10: =IF(OFFSET(Gemini抽出データ!$A$1,AE8,1)=0,"",OFFSET(Gemini抽出データ!$A$1,AE8,1)) | AH10: ="学年"&AH$1 -> 学年60 | AI10: =IF(OFFSET(Gemini抽出データ!$A$1,AH8,1)=0,"",OFFSET(Gemini抽出データ!$A$1,AH8,1)) | AK10: ="種類"&AK$1 -> 種類85 | AL10: =IF(OFFSET(Gemini抽出データ!$A$1,AK8,1)=0,"",OFFSET(Gemini抽出データ!$A$1,AK8,1)) | AN10: ="学年"&AN$1 -> 学年86 | AO10: =IF(OFFSET(Gemini抽出データ!$A$1,AN8,1)=0,"",OFFSET(Gemini抽出データ!$A$1,AN8,1)) | AQ10: ="学年"&AQ$1 -> 学年87 | AR10: =IF(OFFSET(Gemini抽出データ!$A$1,AQ8,1)=0,"",OFFSET(Gemini抽出データ!$A$1,AQ8,1)) | AT10: ="学年"&AT$1 -> 学年88 | AU10: =IF(OFFSET(Gemini抽出データ!$A$1,AT8,1)=0,"",OFFSET(Gemini抽出データ!$A$1,AT8,1)) | AW10: ="種類"&AW$1 -> 種類113 | AX10: =IF(OFFSET(Gemini抽出データ!$A$1,AW8,1)=0,"",OFFSET(Gemini抽出データ!$A$1,AW8,1)) | AZ10: ="学年"&AZ$1 -> 学年114 | BA10: =IF(OFFSET(Gemini抽出データ!$A$1,AZ8,1)=0,"",OFFSET(Gemini抽出データ!$A$1,AZ8,1)) | BC10: ="学年"&BC$1 -> 学年115 | BD10: =IF(OFFSET(Gemini抽出データ!$A$1,BC8,1)=0,"",OFFSET(Gemini抽出データ!$A$1,BC8,1)) | BF10: ="学年"&BF$1 -> 学年116 | BG10: =IF(OFFSET(Gemini抽出データ!$A$1,BF8,1)=0,"",OFFSET(Gemini抽出データ!$A$1,BF8,1)) | BI10: ="種類"&BI$1 -> 種類141 | BJ10: =IF(OFFSET(Gemini抽出データ!$A$1,BI8,1)=0,"",OFFSET(Gemini抽出データ!$A$1,BI8,1)) | BL10: ="学年"&BL$1 -> 学年142 | BM10: =IF(OFFSET(Gemini抽出データ!$A$1,BL8,1)=0,"",OFFSET(Gemini抽出データ!$A$1,BL8,1)) | BO10: ="学年"&BO$1 -> 学年143 | BP10: =IF(OFFSET(Gemini抽出データ!$A$1,BO8,1)=0,"",OFFSET(Gemini抽出データ!$A$1,BO8,1)) | BR10: ="学年"&BR$1 -> 学年144 | BS10: =IF(OFFSET(Gemini抽出データ!$A$1,BR8,1)=0,"",OFFSET(Gemini抽出データ!$A$1,BR8,1)) | BU10: ="種類"&BU$1 -> 種類169 | BV10: =IF(OFFSET(Gemini抽出データ!$A$1,BU8,1)=0,"",OFFSET(Gemini抽出データ!$A$1,BU8,1)) | BX10: ="学年"&BX$1 -> 学年170 | BY10: =IF(OFFSET(Gemini抽出データ!$A$1,BX8,1)=0,"",OFFSET(Gemini抽出データ!$A$1,BX8,1)) | CA10: ="学年"&CA$1 -> 学年171 | CB10: =IF(OFFSET(Gemini抽出データ!$A$1,CA8,1)=0,"",OFFSET(Gemini抽出データ!$A$1,CA8,1)) | CD10: ="学年"&CD$1 -> 学年172 | CE10: =IF(OFFSET(Gemini抽出データ!$A$1,CD8,1)=0,"",OFFSET(Gemini抽出データ!$A$1,CD8,1)) | CG10: ="種類"&CG$1 -> 種類197 | CH10: =IF(OFFSET(Gemini抽出データ!$A$1,CG8,1)=0,"",OFFSET(Gemini抽出データ!$A$1,CG8,1)) | CJ10: ="学年"&CJ$1 -> 学年198 | CK10: =IF(OFFSET(Gemini抽出データ!$A$1,CJ8,1)=0,"",OFFSET(Gemini抽出データ!$A$1,CJ8,1)) | CM10: ="学年"&CM$1 -> 学年199 | CN10: =IF(OFFSET(Gemini抽出データ!$A$1,CM8,1)=0,"",OFFSET(Gemini抽出データ!$A$1,CM8,1)) | CP10: ="学年"&CP$1 -> 学年200 | CQ10: =IF(OFFSET(Gemini抽出データ!$A$1,CP8,1)=0,"",OFFSET(Gemini抽出データ!$A$1,CP8,1)) | CS10: ="種類"&CS$1 -> 種類225 | CT10: =IF(OFFSET(Gemini抽出データ!$A$1,CS8,1)=0,"",OFFSET(Gemini抽出データ!$A$1,CS8,1)) | CV10: ="学年"&CV$1 -> 学年226 | CW10: =IF(OFFSET(Gemini抽出データ!$A$1,CV8,1)=0,"",OFFSET(Gemini抽出データ!$A$1,CV8,1)) | CY10: ="学年"&CY$1 -> 学年227 | CZ10: =IF(OFFSET(Gemini抽出データ!$A$1,CY8,1)=0,"",OFFSET(Gemini抽出データ!$A$1,CY8,1)) | DB10: ="学年"&DB$1 -> 学年228 | DC10: =IF(OFFSET(Gemini抽出データ!$A$1,DB8,1)=0,"",OFFSET(Gemini抽出データ!$A$1,DB8,1)) | DE10: ="種類"&DE$1 -> 種類253 | DF10: =IF(OFFSET(Gemini抽出データ!$A$1,DE8,1)=0,"",OFFSET(Gemini抽出データ!$A$1,DE8,1)) | DH10: ="学年"&DH$1 -> 学年254 | DI10: =IF(OFFSET(Gemini抽出データ!$A$1,DH8,1)=0,"",OFFSET(Gemini抽出データ!$A$1,DH8,1)) | DK10: ="学年"&DK$1 -> 学年255 | DL10: =IF(OFFSET(Gemini抽出データ!$A$1,DK8,1)=0,"",OFFSET(Gemini抽出データ!$A$1,DK8,1)) | DN10: ="学年"&DN$1 -> 学年256 | DO10: =IF(OFFSET(Gemini抽出データ!$A$1,DN8,1)=0,"",OFFSET(Gemini抽出データ!$A$1,DN8,1)) | DQ10: ="種類"&DQ$1 -> 種類281 | DR10: =IF(OFFSET(Gemini抽出データ!$A$1,DQ8,1)=0,"",OFFSET(Gemini抽出データ!$A$1,DQ8,1)) | DT10: ="学年"&DT$1 -> 学年282 | DU10: =IF(OFFSET(Gemini抽出データ!$A$1,DT8,1)=0,"",OFFSET(Gemini抽出データ!$A$1,DT8,1)) | DW10: ="学年"&DW$1 -> 学年283 | DX10: =IF(OFFSET(Gemini抽出データ!$A$1,DW8,1)=0,"",OFFSET(Gemini抽出データ!$A$1,DW8,1)) | DZ10: ="学年"&DZ$1 -> 学年284 | EA10: =IF(OFFSET(Gemini抽出データ!$A$1,DZ8,1)=0,"",OFFSET(Gemini抽出データ!$A$1,DZ8,1)) | EC10: ="種類"&EC$1 -> 種類309 | ED10: =IF(OFFSET(Gemini抽出データ!$A$1,EC8,1)=0,"",OFFSET(Gemini抽出データ!$A$1,EC8,1)) | EF10: ="学年"&EF$1 -> 学年310 | EG10: =IF(OFFSET(Gemini抽出データ!$A$1,EF8,1)=0,"",OFFSET(Gemini抽出データ!$A$1,EF8,1)) | EI10: ="学年"&EI$1 -> 学年311 | EJ10: =IF(OFFSET(Gemini抽出データ!$A$1,EI8,1)=0,"",OFFSET(Gemini抽出データ!$A$1,EI8,1)) | EL10: ="学年"&EL$1 -> 学年312 | EM10: =IF(OFFSET(Gemini抽出データ!$A$1,EL8,1)=0,"",OFFSET(Gemini抽出データ!$A$1,EL8,1)) | EO10: ="種類"&EO$1 -> 種類337 | EP10: =IF(OFFSET(Gemini抽出データ!$A$1,EO8,1)=0,"",OFFSET(Gemini抽出データ!$A$1,EO8,1)) | ER10: ="学年"&ER$1 -> 学年338 | ES10: =IF(OFFSET(Gemini抽出データ!$A$1,ER8,1)=0,"",OFFSET(Gemini抽出データ!$A$1,ER8,1)) | EU10: ="学年"&EU$1 -> 学年339 | EV10: =IF(OFFSET(Gemini抽出データ!$A$1,EU8,1)=0,"",OFFSET(Gemini抽出データ!$A$1,EU8,1)) | EX10: ="学年"&EX$1 -> 学年340 | EY10: =IF(OFFSET(Gemini抽出データ!$A$1,EX8,1)=0,"",OFFSET(Gemini抽出データ!$A$1,EX8,1)) | FA10: ="種類"&FA$1 -> 種類365 | FB10: =IF(OFFSET(Gemini抽出データ!$A$1,FA8,1)=0,"",OFFSET(Gemini抽出データ!$A$1,FA8,1)) | FD10: ="学年"&FD$1 -> 学年366 | FE10: =IF(OFFSET(Gemini抽出データ!$A$1,FD8,1)=0,"",OFFSET(Gemini抽出データ!$A$1,FD8,1)) | FG10: ="学年"&FG$1 -> 学年367 | FH10: =IF(OFFSET(Gemini抽出データ!$A$1,FG8,1)=0,"",OFFSET(Gemini抽出データ!$A$1,FG8,1)) | FJ10: ="学年"&FJ$1 -> 学年368 | FK10: =IF(OFFSET(Gemini抽出データ!$A$1,FJ8,1)=0,"",OFFSET(Gemini抽出データ!$A$1,FJ8,1)) | FM10: ="種類"&FM$1 -> 種類393 | FN10: =IF(OFFSET(Gemini抽出データ!$A$1,FM8,1)=0,"",OFFSET(Gemini抽出データ!$A$1,FM8,1)) | FP10: ="学年"&FP$1 -> 学年394 | FQ10: =IF(OFFSET(Gemini抽出データ!$A$1,FP8,1)=0,"",OFFSET(Gemini抽出データ!$A$1,FP8,1)) | FS10: ="学年"&FS$1 -> 学年395 | FT10: =IF(OFFSET(Gemini抽出データ!$A$1,FS8,1)=0,"",OFFSET(Gemini抽出データ!$A$1,FS8,1)) | FV10: ="学年"&FV$1 -> 学年396 | FW10: =IF(OFFSET(Gemini抽出データ!$A$1,FV8,1)=0,"",OFFSET(Gemini抽出データ!$A$1,FV8,1)) | FY10: ="種類"&FY$1 -> 種類421 | FZ10: =IF(OFFSET(Gemini抽出データ!$A$1,FY8,1)=0,"",OFFSET(Gemini抽出データ!$A$1,FY8,1)) | GB10: ="学年"&GB$1 -> 学年422 | GC10: =IF(OFFSET(Gemini抽出データ!$A$1,GB8,1)=0,"",OFFSET(Gemini抽出データ!$A$1,GB8,1)) | GE10: ="学年"&GE$1 -> 学年423 | GF10: =IF(OFFSET(Gemini抽出データ!$A$1,GE8,1)=0,"",OFFSET(Gemini抽出データ!$A$1,GE8,1)) | GH10: ="学年"&GH$1 -> 学年424 | GI10: =IF(OFFSET(Gemini抽出データ!$A$1,GH8,1)=0,"",OFFSET(Gemini抽出データ!$A$1,GH8,1)) | GK10: ="種類"&GK$1 -> 種類449 | GL10: =IF(OFFSET(Gemini抽出データ!$A$1,GK8,1)=0,"",OFFSET(Gemini抽出データ!$A$1,GK8,1)) | GN10: ="学年"&GN$1 -> 学年450 | GO10: =IF(OFFSET(Gemini抽出データ!$A$1,GN8,1)=0,"",OFFSET(Gemini抽出データ!$A$1,GN8,1)) | GQ10: ="学年"&GQ$1 -> 学年451 | GR10: =IF(OFFSET(Gemini抽出データ!$A$1,GQ8,1)=0,"",OFFSET(Gemini抽出データ!$A$1,GQ8,1)) | GT10: ="学年"&GT$1 -> 学年452 | GU10: =IF(OFFSET(Gemini抽出データ!$A$1,GT8,1)=0,"",OFFSET(Gemini抽出データ!$A$1,GT8,1)) | GW10: ="種類"&GW$1 -> 種類477 | GX10: =IF(OFFSET(Gemini抽出データ!$A$1,GW8,1)=0,"",OFFSET(Gemini抽出データ!$A$1,GW8,1)) | GZ10: ="学年"&GZ$1 -> 学年478 | HA10: =IF(OFFSET(Gemini抽出データ!$A$1,GZ8,1)=0,"",OFFSET(Gemini抽出データ!$A$1,GZ8,1)) | HC10: ="学年"&HC$1 -> 学年479 | HD10: =IF(OFFSET(Gemini抽出データ!$A$1,HC8,1)=0,"",OFFSET(Gemini抽出データ!$A$1,HC8,1)) | HF10: ="学年"&HF$1 -> 学年480 | HG10: =IF(OFFSET(Gemini抽出データ!$A$1,HF8,1)=0,"",OFFSET(Gemini抽出データ!$A$1,HF8,1)) | HI10: ="種類"&HI$1 -> 種類505 | HJ10: =IF(OFFSET(Gemini抽出データ!$A$1,HI8,1)=0,"",OFFSET(Gemini抽出データ!$A$1,HI8,1)) | HL10: ="学年"&HL$1 -> 学年506 | HM10: =IF(OFFSET(Gemini抽出データ!$A$1,HL8,1)=0,"",OFFSET(Gemini抽出データ!$A$1,HL8,1)) | HO10: ="学年"&HO$1 -> 学年507 | HP10: =IF(OFFSET(Gemini抽出データ!$A$1,HO8,1)=0,"",OFFSET(Gemini抽出データ!$A$1,HO8,1)) | HR10: ="学年"&HR$1 -> 学年508 | HS10: =IF(OFFSET(Gemini抽出データ!$A$1,HR8,1)=0,"",OFFSET(Gemini抽出データ!$A$1,HR8,1)) | HU10: =IF(OFFSET(Gemini抽出データ!$A$1,#REF!,1)=0,"",OFFSET(Gemini抽出データ!$A$1,#REF!,1)) -> #REF!
A11: ="学年"&A$1 -> 学年1 | M11: ="学年"&M$1 -> 学年29 | Y11: ="学年"&Y$1 -> 学年57 | AK11: ="学年"&AK$1 -> 学年85 | AW11: ="学年"&AW$1 -> 学年113 | BI11: ="学年"&BI$1 -> 学年141 | BU11: ="学年"&BU$1 -> 学年169 | CG11: ="学年"&CG$1 -> 学年197 | CS11: ="学年"&CS$1 -> 学年225 | DE11: ="学年"&DE$1 -> 学年253 | DQ11: ="学年"&DQ$1 -> 学年281 | EC11: ="学年"&EC$1 -> 学年309 | EO11: ="学年"&EO$1 -> 学年337 | FA11: ="学年"&FA$1 -> 学年365 | FM11: ="学年"&FM$1 -> 学年393 | FY11: ="学年"&FY$1 -> 学年421 | GK11: ="学年"&GK$1 -> 学年449 | GW11: ="学年"&GW$1 -> 学年477 | HI11: ="学年"&HI$1 -> 学年505
B12: =OFFSET(Gemini抽出データ!$A$1,A8,3) -> 0 | E12: =OFFSET(Gemini抽出データ!$A$1,D8,3) -> 0 | H12: =OFFSET(Gemini抽出データ!$A$1,G8,3) -> 0 | K12: =OFFSET(Gemini抽出データ!$A$1,J8,3) -> 0 | N12: =OFFSET(Gemini抽出データ!$A$1,M8,3) -> 0 | Q12: =OFFSET(Gemini抽出データ!$A$1,P8,3) -> 0 | T12: =OFFSET(Gemini抽出データ!$A$1,S8,3) -> 0 | W12: =OFFSET(Gemini抽出データ!$A$1,V8,3) -> 0 | Z12: =OFFSET(Gemini抽出データ!$A$1,Y8,3) -> 0 | AC12: =OFFSET(Gemini抽出データ!$A$1,AB8,3) -> 0 | AF12: =OFFSET(Gemini抽出データ!$A$1,AE8,3) -> 0 | AI12: =OFFSET(Gemini抽出データ!$A$1,AH8,3) -> 0 | AL12: =OFFSET(Gemini抽出データ!$A$1,AK8,3) -> 0 | AO12: =OFFSET(Gemini抽出データ!$A$1,AN8,3) -> 0 | AR12: =OFFSET(Gemini抽出データ!$A$1,AQ8,3) -> 0 | AU12: =OFFSET(Gemini抽出データ!$A$1,AT8,3) -> 0 | AX12: =OFFSET(Gemini抽出データ!$A$1,AW8,3) -> 0 | BA12: =OFFSET(Gemini抽出データ!$A$1,AZ8,3) -> 0 | BD12: =OFFSET(Gemini抽出データ!$A$1,BC8,3) -> 0 | BG12: =OFFSET(Gemini抽出データ!$A$1,BF8,3) -> 0 | BJ12: =OFFSET(Gemini抽出データ!$A$1,BI8,3) -> 0 | BM12: =OFFSET(Gemini抽出データ!$A$1,BL8,3) -> 0 | BP12: =OFFSET(Gemini抽出データ!$A$1,BO8,3) -> 0 | BS12: =OFFSET(Gemini抽出データ!$A$1,BR8,3) -> 0 | BV12: =OFFSET(Gemini抽出データ!$A$1,BU8,3) -> 0 | BY12: =OFFSET(Gemini抽出データ!$A$1,BX8,3) -> 0 | CB12: =OFFSET(Gemini抽出データ!$A$1,CA8,3) -> 0 | CE12: =OFFSET(Gemini抽出データ!$A$1,CD8,3) -> 0 | CH12: =OFFSET(Gemini抽出データ!$A$1,CG8,3) -> 0 | CK12: =OFFSET(Gemini抽出データ!$A$1,CJ8,3) -> 0 | CN12: =OFFSET(Gemini抽出データ!$A$1,CM8,3) -> 0 | CQ12: =OFFSET(Gemini抽出データ!$A$1,CP8,3) -> 0 | CT12: =OFFSET(Gemini抽出データ!$A$1,CS8,3) -> 0 | CW12: =OFFSET(Gemini抽出データ!$A$1,CV8,3) -> 0 | CZ12: =OFFSET(Gemini抽出データ!$A$1,CY8,3) -> 0 | DC12: =OFFSET(Gemini抽出データ!$A$1,DB8,3) -> 0 | DF12: =OFFSET(Gemini抽出データ!$A$1,DE8,3) -> 0 | DI12: =OFFSET(Gemini抽出データ!$A$1,DH8,3) -> 0 | DL12: =OFFSET(Gemini抽出データ!$A$1,DK8,3) -> 0 | DO12: =OFFSET(Gemini抽出データ!$A$1,DN8,3) -> 0 | DR12: =OFFSET(Gemini抽出データ!$A$1,DQ8,3) -> 0 | DU12: =OFFSET(Gemini抽出データ!$A$1,DT8,3) -> 0 | DX12: =OFFSET(Gemini抽出データ!$A$1,DW8,3) -> 0 | EA12: =OFFSET(Gemini抽出データ!$A$1,DZ8,3) -> 0 | ED12: =OFFSET(Gemini抽出データ!$A$1,EC8,3) -> 0 | EG12: =OFFSET(Gemini抽出データ!$A$1,EF8,3) -> 0 | EJ12: =OFFSET(Gemini抽出データ!$A$1,EI8,3) -> 0 | EM12: =OFFSET(Gemini抽出データ!$A$1,EL8,3) -> 0 | EP12: =OFFSET(Gemini抽出データ!$A$1,EO8,3) -> 0 | ES12: =OFFSET(Gemini抽出データ!$A$1,ER8,3) -> 0 | EV12: =OFFSET(Gemini抽出データ!$A$1,EU8,3) -> 0 | EY12: =OFFSET(Gemini抽出データ!$A$1,EX8,3) -> 0 | FB12: =OFFSET(Gemini抽出データ!$A$1,FA8,3) -> 0 | FE12: =OFFSET(Gemini抽出データ!$A$1,FD8,3) -> 0 | FH12: =OFFSET(Gemini抽出データ!$A$1,FG8,3) -> 0 | FK12: =OFFSET(Gemini抽出データ!$A$1,FJ8,3) -> 0 | FN12: =OFFSET(Gemini抽出データ!$A$1,FM8,3) -> 0 | FQ12: =OFFSET(Gemini抽出データ!$A$1,FP8,3) -> 0 | FT12: =OFFSET(Gemini抽出データ!$A$1,FS8,3) -> 0 | FW12: =OFFSET(Gemini抽出データ!$A$1,FV8,3) -> 0 | FZ12: =OFFSET(Gemini抽出データ!$A$1,FY8,3) -> 0 | GC12: =OFFSET(Gemini抽出データ!$A$1,GB8,3) -> 0 | GF12: =OFFSET(Gemini抽出データ!$A$1,GE8,3) -> 0 | GI12: =OFFSET(Gemini抽出データ!$A$1,GH8,3) -> 0 | GL12: =OFFSET(Gemini抽出データ!$A$1,GK8,3) -> 0 | GO12: =OFFSET(Gemini抽出データ!$A$1,GN8,3) -> 0 | GR12: =OFFSET(Gemini抽出データ!$A$1,GQ8,3) -> 0 | GU12: =OFFSET(Gemini抽出データ!$A$1,GT8,3) -> 0 | GX12: =OFFSET(Gemini抽出データ!$A$1,GW8,3) -> 0 | HA12: =OFFSET(Gemini抽出データ!$A$1,GZ8,3) -> 0 | HD12: =OFFSET(Gemini抽出データ!$A$1,HC8,3) -> 0 | HG12: =OFFSET(Gemini抽出データ!$A$1,HF8,3) -> 0 | HJ12: =OFFSET(Gemini抽出データ!$A$1,HI8,3) -> 0 | HM12: =OFFSET(Gemini抽出データ!$A$1,HL8,3) -> 0 | HP12: =OFFSET(Gemini抽出データ!$A$1,HO8,3) -> 0 | HS12: =OFFSET(Gemini抽出データ!$A$1,HR8,3) -> 0 | HU12: =OFFSET(Gemini抽出データ!$A$1,#REF!,3) -> #REF!
